Workbook

Sheet PRODUÇÃO
A1: CONTROLE DE PRODUÇÃO LINHA DE ACABAMENTO
A2: RASTREABILIDADE | G2: PRODUÇÃO EM PEÇAS | L2: PRODUÇÃO EM TON.
A3: Ano | B3: Mês | C3: Data | D3: OPERADOR | E3: TURNO | F3: PRODUTO | G3: LIBERADAS | H3: REJATO | I3: REFUGO | J3: RETRABALHO | K3: TOTAL | L3: LIBERADAS | M3: REJATO | N3: REFUGO | O3: RETRABALHO | P3: Total acabado | Q3: Nome do produto | R3: Cliente | S3: Tempo Teórico | AJ3: 1 | AK3: JANEIRO
A4: =IF(C4=0,0,YEAR(C4)) -> 2019 | B4: =IF(C4>0,VLOOKUP(MONTH($C4),$AJ$3:$AK$14,2,0),0) -> SETEMBRO | C4: 43710 | E4: 1 | F4: 13 | G4: 800 | H4: 320 | I4: 150 | J4: 320 | K4: =SUM(G4:J4) -> 1590 | L4: =IF(ISERROR(VLOOKUP($F4,#REF!,6,0)*G4/1000),0,VLOOKUP($F4,#REF!,6,0)*G4/1000) -> 0 | M4: =IF(ISERROR(VLOOKUP($F4,#REF!,6,0)*H4/1000),0,VLOOKUP($F4,#REF!,6,0)*H4/1000) -> 0 | N4: =IF(ISERROR(VLOOKUP($F4,#REF!,6,0)*I4/1000),0,VLOOKUP($F4,#REF!,6,0)*I4/1000) -> 0 | O4: =IF(ISERROR(VLOOKUP($F4,#REF!,6,0)*J4/1000),0,VLOOKUP($F4,#REF!,6,0)*J4/1000) -> 0 | P4: =IF(ISERROR(VLOOKUP($F4,#REF!,6,0)*K4/1000),0,VLOOKUP($F4,#REF!,6,0)*K4/1000) -> 0 | Q4: =IF(ISERROR(VLOOKUP(F4,#REF!,3,0)),0,VLOOKUP(F4,#REF!,3,0)) -> 0 | R4: =IF(ISERROR(VLOOKUP(F4,#REF!,4,0)),0,VLOOKUP(F4,#REF!,4,0)) -> 0 | S4: =IF(ISERROR(VLOOKUP(F4,#REF!,4,0)),0,VLOOKUP(F4,#REF!,10,0)/60*K4) -> 0 | AJ4: 2 | AK4: FEVEREIRO
A5: =IF(C5=0,0,YEAR(C5)) -> 2019 | B5: =IF(C5>0,VLOOKUP(MONTH($C5),$AJ$3:$AK$14,2,0),0) -> SETEMBRO | C5: 43710 | E5: 1 | F5: 3 | G5: 1020 | I5: 30 | J5: 676 | K5: =SUM(G5:J5) -> 1726 | L5: =IF(ISERROR(VLOOKUP($F5,#REF!,6,0)*G5/1000),0,VLOOKUP($F5,#REF!,6,0)*G5/1000) -> 0 | M5: =IF(ISERROR(VLOOKUP($F5,#REF!,6,0)*H5/1000),0,VLOOKUP($F5,#REF!,6,0)*H5/1000) -> 0 | N5: =IF(ISERROR(VLOOKUP($F5,#REF!,6,0)*I5/1000),0,VLOOKUP($F5,#REF!,6,0)*I5/1000) -> 0 | O5: =IF(ISERROR(VLOOKUP($F5,#REF!,6,0)*J5/1000),0,VLOOKUP($F5,#REF!,6,0)*J5/1000) -> 0 | P5: =IF(ISERROR(VLOOKUP(F5,#REF!,6,0)*K5/1000),0,VLOOKUP(F5,#REF!,6,0)*K5/1000) -> 0 | Q5: =IF(ISERROR(VLOOKUP(F5,#REF!,3,0)),0,VLOOKUP(F5,#REF!,3,0)) -> 0 | R5: =IF(ISERROR(VLOOKUP(F5,#REF!,4,0)),0,VLOOKUP(F5,#REF!,4,0)) -> 0 | S5: =IF(ISERROR(VLOOKUP(F5,#REF!,4,0)),0,VLOOKUP(F5,#REF!,10,0)/60*K5) -> 0 | AJ5: 3 | AK5: MARÇO
A6: =IF(C6=0,0,YEAR(C6)) -> 2019 | B6: =IF(C6>0,VLOOKUP(MONTH($C6),$AJ$3:$AK$14,2,0),0) -> SETEMBRO | C6: 43710 | E6: 2 | F6: 3 | G6: 1080 | I6: 103 | J6: 2860 | K6: =SUM(G6:J6) -> 4043 | L6: =IF(ISERROR(VLOOKUP($F6,#REF!,6,0)*G6/1000),0,VLOOKUP($F6,#REF!,6,0)*G6/1000) -> 0 | M6: =IF(ISERROR(VLOOKUP($F6,#REF!,6,0)*H6/1000),0,VLOOKUP($F6,#REF!,6,0)*H6/1000) -> 0 | N6: =IF(ISERROR(VLOOKUP($F6,#REF!,6,0)*I6/1000),0,VLOOKUP($F6,#REF!,6,0)*I6/1000) -> 0 | O6: =IF(ISERROR(VLOOKUP($F6,#REF!,6,0)*J6/1000),0,VLOOKUP($F6,#REF!,6,0)*J6/1000) -> 0 | P6: =IF(ISERROR(VLOOKUP(F6,#REF!,6,0)*K6/1000),0,VLOOKUP(F6,#REF!,6,0)*K6/1000) -> 0 | Q6: =IF(ISERROR(VLOOKUP(F6,#REF!,3,0)),0,VLOOKUP(F6,#REF!,3,0)) -> 0 | R6: =IF(ISERROR(VLOOKUP(F6,#REF!,4,0)),0,VLOOKUP(F6,#REF!,4,0)) -> 0 | S6: =IF(ISERROR(VLOOKUP(F6,#REF!,4,0)),0,VLOOKUP(F6,#REF!,10,0)/60*K6) -> 0 | AJ6: 4 | AK6: ABRIL
A7: =IF(C7=0,0,YEAR(C7)) -> 2019 | B7: =IF(C7>0,VLOOKUP(MONTH($C7),$AJ$3:$AK$14,2,0),0) -> SETEMBRO | C7: 43710 | E7: 1 | F7: 49 | G7: 406 | K7: =SUM(G7:J7) -> 406 | L7: =IF(ISERROR(VLOOKUP($F7,#REF!,6,0)*G7/1000),0,VLOOKUP($F7,#REF!,6,0)*G7/1000) -> 0 | M7: =IF(ISERROR(VLOOKUP($F7,#REF!,6,0)*H7/1000),0,VLOOKUP($F7,#REF!,6,0)*H7/1000) -> 0 | N7: =IF(ISERROR(VLOOKUP($F7,#REF!,6,0)*I7/1000),0,VLOOKUP($F7,#REF!,6,0)*I7/1000) -> 0 | O7: =IF(ISERROR(VLOOKUP($F7,#REF!,6,0)*J7/1000),0,VLOOKUP($F7,#REF!,6,0)*J7/1000) -> 0 | P7: =IF(ISERROR(VLOOKUP(F7,#REF!,6,0)*K7/1000),0,VLOOKUP(F7,#REF!,6,0)*K7/1000) -> 0 | Q7: =IF(ISERROR(VLOOKUP(F7,#REF!,3,0)),0,VLOOKUP(F7,#REF!,3,0)) -> 0 | R7: =IF(ISERROR(VLOOKUP(F7,#REF!,4,0)),0,VLOOKUP(F7,#REF!,4,0)) -> 0 | S7: =IF(ISERROR(VLOOKUP(F7,#REF!,4,0)),0,VLOOKUP(F7,#REF!,10,0)/60*K7) -> 0 | AJ7: 5 | AK7: MAIO
A8: =IF(C8=0,0,YEAR(C8)) -> 2019 | B8: =IF(C8>0,VLOOKUP(MONTH($C8),$AJ$3:$AK$14,2,0),0) -> SETEMBRO | C8: 43710 | E8: 1 | F8: 43 | G8: 273 | H8: 150 | I8: 90 | K8: =SUM(G8:J8) -> 513 | L8: =IF(ISERROR(VLOOKUP($F8,#REF!,6,0)*G8/1000),0,VLOOKUP($F8,#REF!,6,0)*G8/1000) -> 0 | M8: =IF(ISERROR(VLOOKUP($F8,#REF!,6,0)*H8/1000),0,VLOOKUP($F8,#REF!,6,0)*H8/1000) -> 0 | N8: =IF(ISERROR(VLOOKUP($F8,#REF!,6,0)*I8/1000),0,VLOOKUP($F8,#REF!,6,0)*I8/1000) -> 0 | O8: =IF(ISERROR(VLOOKUP($F8,#REF!,6,0)*J8/1000),0,VLOOKUP($F8,#REF!,6,0)*J8/1000) -> 0 | P8: =IF(ISERROR(VLOOKUP(F8,#REF!,6,0)*K8/1000),0,VLOOKUP(F8,#REF!,6,0)*K8/1000) -> 0 | Q8: =IF(ISERROR(VLOOKUP(F8,#REF!,3,0)),0,VLOOKUP(F8,#REF!,3,0)) -> 0 | R8: =IF(ISERROR(VLOOKUP(F8,#REF!,4,0)),0,VLOOKUP(F8,#REF!,4,0)) -> 0 | S8: =IF(ISERROR(VLOOKUP(F8,#REF!,4,0)),0,VLOOKUP(F8,#REF!,10,0)/60*K8) -> 0 | AJ8: 6 | AK8: JUNHO
A9: =IF(C9=0,0,YEAR(C9)) -> 2019 | B9: =IF(C9>0,VLOOKUP(MONTH($C9),$AJ$3:$AK$14,2,0),0) -> SETEMBRO | C9: 43710 | E9: 1 | F9: 44 | G9: 0 | H9: 80 | K9: =SUM(G9:J9) -> 80 | L9: =IF(ISERROR(VLOOKUP($F9,#REF!,6,0)*G9/1000),0,VLOOKUP($F9,#REF!,6,0)*G9/1000) -> 0 | M9: =IF(ISERROR(VLOOKUP($F9,#REF!,6,0)*H9/1000),0,VLOOKUP($F9,#REF!,6,0)*H9/1000) -> 0 | N9: =IF(ISERROR(VLOOKUP($F9,#REF!,6,0)*I9/1000),0,VLOOKUP($F9,#REF!,6,0)*I9/1000) -> 0 | O9: =IF(ISERROR(VLOOKUP($F9,#REF!,6,0)*J9/1000),0,VLOOKUP($F9,#REF!,6,0)*J9/1000) -> 0 | P9: =IF(ISERROR(VLOOKUP(F9,#REF!,6,0)*K9/1000),0,VLOOKUP(F9,#REF!,6,0)*K9/1000) -> 0 | Q9: =IF(ISERROR(VLOOKUP(F9,#REF!,3,0)),0,VLOOKUP(F9,#REF!,3,0)) -> 0 | R9: =IF(ISERROR(VLOOKUP(F9,#REF!,4,0)),0,VLOOKUP(F9,#REF!,4,0)) -> 0 | S9: =IF(ISERROR(VLOOKUP(F9,#REF!,4,0)),0,VLOOKUP(F9,#REF!,10,0)/60*K9) -> 0 | AJ9: 7 | AK9: JULHO
A10: =IF(C10=0,0,YEAR(C10)) -> 2019 | B10: =IF(C10>0,VLOOKUP(MONTH($C10),$AJ$3:$AK$14,2,0),0) -> SETEMBRO | C10: 43710 | E10: 1 | F10: 12 | G10: 739 | I10: 219 | K10: =SUM(G10:J10) -> 958 | L10: =IF(ISERROR(VLOOKUP($F10,#REF!,6,0)*G10/1000),0,VLOOKUP($F10,#REF!,6,0)*G10/1000) -> 0 | M10: =IF(ISERROR(VLOOKUP($F10,#REF!,6,0)*H10/1000),0,VLOOKUP($F10,#REF!,6,0)*H10/1000) -> 0 | N10: =IF(ISERROR(VLOOKUP($F10,#REF!,6,0)*I10/1000),0,VLOOKUP($F10,#REF!,6,0)*I10/1000) -> 0 | O10: =IF(ISERROR(VLOOKUP($F10,#REF!,6,0)*J10/1000),0,VLOOKUP($F10,#REF!,6,0)*J10/1000) -> 0 | P10: =IF(ISERROR(VLOOKUP(F10,#REF!,6,0)*K10/1000),0,VLOOKUP(F10,#REF!,6,0)*K10/1000) -> 0 | Q10: =IF(ISERROR(VLOOKUP(F10,#REF!,3,0)),0,VLOOKUP(F10,#REF!,3,0)) -> 0 | R10: =IF(ISERROR(VLOOKUP(F10,#REF!,4,0)),0,VLOOKUP(F10,#REF!,4,0)) -> 0 | S10: =IF(ISERROR(VLOOKUP(F10,#REF!,4,0)),0,VLOOKUP(F10,#REF!,10,0)/60*K10) -> 0 | AJ10: 8 | AK10: AGOSTO
A11: =IF(C11=0,0,YEAR(C11)) -> 2019 | B11: =IF(C11>0,VLOOKUP(MONTH($C11),$AJ$3:$AK$14,2,0),0) -> SETEMBRO | C11: 43710 | E11: 2 | F11: 50 | G11: 595 | K11: =SUM(G11:J11) -> 595 | L11: =IF(ISERROR(VLOOKUP($F11,#REF!,6,0)*G11/1000),0,VLOOKUP($F11,#REF!,6,0)*G11/1000) -> 0 | M11: =IF(ISERROR(VLOOKUP($F11,#REF!,6,0)*H11/1000),0,VLOOKUP($F11,#REF!,6,0)*H11/1000) -> 0 | N11: =IF(ISERROR(VLOOKUP($F11,#REF!,6,0)*I11/1000),0,VLOOKUP($F11,#REF!,6,0)*I11/1000) -> 0 | O11: =IF(ISERROR(VLOOKUP($F11,#REF!,6,0)*J11/1000),0,VLOOKUP($F11,#REF!,6,0)*J11/1000) -> 0 | P11: =IF(ISERROR(VLOOKUP(F11,#REF!,6,0)*K11/1000),0,VLOOKUP(F11,#REF!,6,0)*K11/1000) -> 0 | Q11: =IF(ISERROR(VLOOKUP(F11,#REF!,3,0)),0,VLOOKUP(F11,#REF!,3,0)) -> 0 | R11: =IF(ISERROR(VLOOKUP(F11,#REF!,4,0)),0,VLOOKUP(F11,#REF!,4,0)) -> 0 | S11: =IF(ISERROR(VLOOKUP(F11,#REF!,4,0)),0,VLOOKUP(F11,#REF!,10,0)/60*K11) -> 0 | AJ11: 9 | AK11: SETEMBRO
A12: =IF(C12=0,0,YEAR(C12)) -> 2019 | B12: =IF(C12>0,VLOOKUP(MONTH($C12),$AJ$3:$AK$14,2,0),0) -> SETEMBRO | C12: 43710 | E12: 2 | F12: 49 | G12: 249 | K12: =SUM(G12:J12) -> 249 | L12: =IF(ISERROR(VLOOKUP($F12,#REF!,6,0)*G12/1000),0,VLOOKUP($F12,#REF!,6,0)*G12/1000) -> 0 | M12: =IF(ISERROR(VLOOKUP($F12,#REF!,6,0)*H12/1000),0,VLOOKUP($F12,#REF!,6,0)*H12/1000) -> 0 | N12: =IF(ISERROR(VLOOKUP($F12,#REF!,6,0)*I12/1000),0,VLOOKUP($F12,#REF!,6,0)*I12/1000) -> 0 | O12: =IF(ISERROR(VLOOKUP($F12,#REF!,6,0)*J12/1000),0,VLOOKUP($F12,#REF!,6,0)*J12/1000) -> 0 | P12: =IF(ISERROR(VLOOKUP(F12,#REF!,6,0)*K12/1000),0,VLOOKUP(F12,#REF!,6,0)*K12/1000) -> 0 | Q12: =IF(ISERROR(VLOOKUP(F12,#REF!,3,0)),0,VLOOKUP(F12,#REF!,3,0)) -> 0 | R12: =IF(ISERROR(VLOOKUP(F12,#REF!,4,0)),0,VLOOKUP(F12,#REF!,4,0)) -> 0 | S12: =IF(ISERROR(VLOOKUP(F12,#REF!,4,0)),0,VLOOKUP(F12,#REF!,10,0)/60*K12) -> 0 | AJ12: 10 | AK12: OUTUBRO
A13: =IF(C13=0,0,YEAR(C13)) -> 2019 | B13: =IF(C13>0,VLOOKUP(MONTH($C13),$AJ$3:$AK$14,2,0),0) -> SETEMBRO | C13: 43710 | E13: 2 | F13: 44 | G13: 655 | H13: 317 | I13: 299 | K13: =SUM(G13:J13) -> 1271 | L13: =IF(ISERROR(VLOOKUP($F13,#REF!,6,0)*G13/1000),0,VLOOKUP($F13,#REF!,6,0)*G13/1000) -> 0 | M13: =IF(ISERROR(VLOOKUP($F13,#REF!,6,0)*H13/1000),0,VLOOKUP($F13,#REF!,6,0)*H13/1000) -> 0 | N13: =IF(ISERROR(VLOOKUP($F13,#REF!,6,0)*I13/1000),0,VLOOKUP($F13,#REF!,6,0)*I13/1000) -> 0 | O13: =IF(ISERROR(VLOOKUP($F13,#REF!,6,0)*J13/1000),0,VLOOKUP($F13,#REF!,6,0)*J13/1000) -> 0 | P13: =IF(ISERROR(VLOOKUP(F13,#REF!,6,0)*K13/1000),0,VLOOKUP(F13,#REF!,6,0)*K13/1000) -> 0 | Q13: =IF(ISERROR(VLOOKUP(F13,#REF!,3,0)),0,VLOOKUP(F13,#REF!,3,0)) -> 0 | R13: =IF(ISERROR(VLOOKUP(F13,#REF!,4,0)),0,VLOOKUP(F13,#REF!,4,0)) -> 0 | S13: =IF(ISERROR(VLOOKUP(F13,#REF!,4,0)),0,VLOOKUP(F13,#REF!,10,0)/60*K13) -> 0 | AJ13: 11 | AK13: NOVEMBRO
A14: =IF(C14=0,0,YEAR(C14)) -> 2019 | B14: =IF(C14>0,VLOOKUP(MONTH($C14),$AJ$3:$AK$14,2,0),0) -> SETEMBRO | C14: 43710 | E14: 3 | F14: 3 | G14: 635 | I14: 5 | J14: 100 | K14: =SUM(G14:J14) -> 740 | L14: =IF(ISERROR(VLOOKUP($F14,#REF!,6,0)*G14/1000),0,VLOOKUP($F14,#REF!,6,0)*G14/1000) -> 0 | M14: =IF(ISERROR(VLOOKUP($F14,#REF!,6,0)*H14/1000),0,VLOOKUP($F14,#REF!,6,0)*H14/1000) -> 0 | N14: =IF(ISERROR(VLOOKUP($F14,#REF!,6,0)*I14/1000),0,VLOOKUP($F14,#REF!,6,0)*I14/1000) -> 0 | O14: =IF(ISERROR(VLOOKUP($F14,#REF!,6,0)*J14/1000),0,VLOOKUP($F14,#REF!,6,0)*J14/1000) -> 0 | P14: =IF(ISERROR(VLOOKUP(F14,#REF!,6,0)*K14/1000),0,VLOOKUP(F14,#REF!,6,0)*K14/1000) -> 0 | Q14: =IF(ISERROR(VLOOKUP(F14,#REF!,3,0)),0,VLOOKUP(F14,#REF!,3,0)) -> 0 | R14: =IF(ISERROR(VLOOKUP(F14,#REF!,4,0)),0,VLOOKUP(F14,#REF!,4,0)) -> 0 | S14: =IF(ISERROR(VLOOKUP(F14,#REF!,4,0)),0,VLOOKUP(F14,#REF!,10,0)/60*K14) -> 0 | AJ14: 12 | AK14: DEZEMBRO
A15: =IF(C15=0,0,YEAR(C15)) -> 2019 | B15: =IF(C15>0,VLOOKUP(MONTH($C15),$AJ$3:$AK$14,2,0),0) -> SETEMBRO | C15: 43711 | E15: 1 | F15: 3 | G15: 1080 | I15: 30 | J15: 250 | K15: =SUM(G15:J15) -> 1360 | L15: =IF(ISERROR(VLOOKUP($F15,#REF!,6,0)*G15/1000),0,VLOOKUP($F15,#REF!,6,0)*G15/1000) -> 0 | M15: =IF(ISERROR(VLOOKUP($F15,#REF!,6,0)*H15/1000),0,VLOOKUP($F15,#REF!,6,0)*H15/1000) -> 0 | N15: =IF(ISERROR(VLOOKUP($F15,#REF!,6,0)*I15/1000),0,VLOOKUP($F15,#REF!,6,0)*I15/1000) -> 0 | O15: =IF(ISERROR(VLOOKUP($F15,#REF!,6,0)*J15/1000),0,VLOOKUP($F15,#REF!,6,0)*J15/1000) -> 0 | P15: =IF(ISERROR(VLOOKUP(F15,#REF!,6,0)*K15/1000),0,VLOOKUP(F15,#REF!,6,0)*K15/1000) -> 0 | Q15: =IF(ISERROR(VLOOKUP(F15,#REF!,3,0)),0,VLOOKUP(F15,#REF!,3,0)) -> 0 | R15: =IF(ISERROR(VLOOKUP(F15,#REF!,4,0)),0,VLOOKUP(F15,#REF!,4,0)) -> 0 | S15: =IF(ISERROR(VLOOKUP(F15,#REF!,4,0)),0,VLOOKUP(F15,#REF!,10,0)/60*K15) -> 0
A16: =IF(C16=0,0,YEAR(C16)) -> 2019 | B16: =IF(C16>0,VLOOKUP(MONTH($C16),$AJ$3:$AK$14,2,0),0) -> SETEMBRO | C16: 43711 | E16: 1 | F16: 49 | G16: 320 | K16: =SUM(G16:J16) -> 320 | L16: =IF(ISERROR(VLOOKUP($F16,#REF!,6,0)*G16/1000),0,VLOOKUP($F16,#REF!,6,0)*G16/1000) -> 0 | M16: =IF(ISERROR(VLOOKUP($F16,#REF!,6,0)*H16/1000),0,VLOOKUP($F16,#REF!,6,0)*H16/1000) -> 0 | N16: =IF(ISERROR(VLOOKUP($F16,#REF!,6,0)*I16/1000),0,VLOOKUP($F16,#REF!,6,0)*I16/1000) -> 0 | O16: =IF(ISERROR(VLOOKUP($F16,#REF!,6,0)*J16/1000),0,VLOOKUP($F16,#REF!,6,0)*J16/1000) -> 0 | P16: =IF(ISERROR(VLOOKUP(F16,#REF!,6,0)*K16/1000),0,VLOOKUP(F16,#REF!,6,0)*K16/1000) -> 0 | Q16: =IF(ISERROR(VLOOKUP(F16,#REF!,3,0)),0,VLOOKUP(F16,#REF!,3,0)) -> 0 | R16: =IF(ISERROR(VLOOKUP(F16,#REF!,4,0)),0,VLOOKUP(F16,#REF!,4,0)) -> 0 | S16: =IF(ISERROR(VLOOKUP(F16,#REF!,4,0)),0,VLOOKUP(F16,#REF!,10,0)/60*K16) -> 0
A17: =IF(C17=0,0,YEAR(C17)) -> 2019 | B17: =IF(C17>0,VLOOKUP(MONTH($C17),$AJ$3:$AK$14,2,0),0) -> SETEMBRO | C17: 43711 | E17: 1 | F17: 44 | G17: 204 | K17: =SUM(G17:J17) -> 204 | L17: =IF(ISERROR(VLOOKUP($F17,#REF!,6,0)*G17/1000),0,VLOOKUP($F17,#REF!,6,0)*G17/1000) -> 0 | M17: =IF(ISERROR(VLOOKUP($F17,#REF!,6,0)*H17/1000),0,VLOOKUP($F17,#REF!,6,0)*H17/1000) -> 0 | N17: =IF(ISERROR(VLOOKUP($F17,#REF!,6,0)*I17/1000),0,VLOOKUP($F17,#REF!,6,0)*I17/1000) -> 0 | O17: =IF(ISERROR(VLOOKUP($F17,#REF!,6,0)*J17/1000),0,VLOOKUP($F17,#REF!,6,0)*J17/1000) -> 0 | P17: =IF(ISERROR(VLOOKUP(F17,#REF!,6,0)*K17/1000),0,VLOOKUP(F17,#REF!,6,0)*K17/1000) -> 0 | Q17: =IF(ISERROR(VLOOKUP(F17,#REF!,3,0)),0,VLOOKUP(F17,#REF!,3,0)) -> 0 | R17: =IF(ISERROR(VLOOKUP(F17,#REF!,4,0)),0,VLOOKUP(F17,#REF!,4,0)) -> 0 | S17: =IF(ISERROR(VLOOKUP(F17,#REF!,4,0)),0,VLOOKUP(F17,#REF!,10,0)/60*K17) -> 0
A18: =IF(C18=0,0,YEAR(C18)) -> 2019 | B18: =IF(C18>0,VLOOKUP(MONTH($C18),$AJ$3:$AK$14,2,0),0) -> SETEMBRO | C18: 43711 | E18: 1 | F18: 51 | G18: 565 | H18: 150 | K18: =SUM(G18:J18) -> 715 | L18: =IF(ISERROR(VLOOKUP($F18,#REF!,6,0)*G18/1000),0,VLOOKUP($F18,#REF!,6,0)*G18/1000) -> 0 | M18: =IF(ISERROR(VLOOKUP($F18,#REF!,6,0)*H18/1000),0,VLOOKUP($F18,#REF!,6,0)*H18/1000) -> 0 | N18: =IF(ISERROR(VLOOKUP($F18,#REF!,6,0)*I18/1000),0,VLOOKUP($F18,#REF!,6,0)*I18/1000) -> 0 | O18: =IF(ISERROR(VLOOKUP($F18,#REF!,6,0)*J18/1000),0,VLOOKUP($F18,#REF!,6,0)*J18/1000) -> 0 | P18: =IF(ISERROR(VLOOKUP(F18,#REF!,6,0)*K18/1000),0,VLOOKUP(F18,#REF!,6,0)*K18/1000) -> 0 | Q18: =IF(ISERROR(VLOOKUP(F18,#REF!,3,0)),0,VLOOKUP(F18,#REF!,3,0)) -> 0 | R18: =IF(ISERROR(VLOOKUP(F18,#REF!,4,0)),0,VLOOKUP(F18,#REF!,4,0)) -> 0 | S18: =IF(ISERROR(VLOOKUP(F18,#REF!,4,0)),0,VLOOKUP(F18,#REF!,10,0)/60*K18) -> 0
A19: =IF(C19=0,0,YEAR(C19)) -> 2019 | B19: =IF(C19>0,VLOOKUP(MONTH($C19),$AJ$3:$AK$14,2,0),0) -> SETEMBRO | C19: 43711 | E19: 1 | F19: 11 | G19: 631 | K19: =SUM(G19:J19) -> 631 | L19: =IF(ISERROR(VLOOKUP($F19,#REF!,6,0)*G19/1000),0,VLOOKUP($F19,#REF!,6,0)*G19/1000) -> 0 | M19: =IF(ISERROR(VLOOKUP($F19,#REF!,6,0)*H19/1000),0,VLOOKUP($F19,#REF!,6,0)*H19/1000) -> 0 | N19: =IF(ISERROR(VLOOKUP($F19,#REF!,6,0)*I19/1000),0,VLOOKUP($F19,#REF!,6,0)*I19/1000) -> 0 | O19: =IF(ISERROR(VLOOKUP($F19,#REF!,6,0)*J19/1000),0,VLOOKUP($F19,#REF!,6,0)*J19/1000) -> 0 | P19: =IF(ISERROR(VLOOKUP(F19,#REF!,6,0)*K19/1000),0,VLOOKUP(F19,#REF!,6,0)*K19/1000) -> 0 | Q19: =IF(ISERROR(VLOOKUP(F19,#REF!,3,0)),0,VLOOKUP(F19,#REF!,3,0)) -> 0 | R19: =IF(ISERROR(VLOOKUP(F19,#REF!,4,0)),0,VLOOKUP(F19,#REF!,4,0)) -> 0 | S19: =IF(ISERROR(VLOOKUP(F19,#REF!,4,0)),0,VLOOKUP(F19,#REF!,10,0)/60*K19) -> 0
A20: =IF(C20=0,0,YEAR(C20)) -> 2019 | B20: =IF(C20>0,VLOOKUP(MONTH($C20),$AJ$3:$AK$14,2,0),0) -> SETEMBRO | C20: 43711 | E20: 2 | F20: 50 | I20: 601 | K20: =SUM(G20:J20) -> 601 | L20: =IF(ISERROR(VLOOKUP($F20,#REF!,6,0)*G20/1000),0,VLOOKUP($F20,#REF!,6,0)*G20/1000) -> 0 | M20: =IF(ISERROR(VLOOKUP($F20,#REF!,6,0)*H20/1000),0,VLOOKUP($F20,#REF!,6,0)*H20/1000) -> 0 | N20: =IF(ISERROR(VLOOKUP($F20,#REF!,6,0)*I20/1000),0,VLOOKUP($F20,#REF!,6,0)*I20/1000) -> 0 | O20: =IF(ISERROR(VLOOKUP($F20,#REF!,6,0)*J20/1000),0,VLOOKUP($F20,#REF!,6,0)*J20/1000) -> 0 | P20: =IF(ISERROR(VLOOKUP(F20,#REF!,6,0)*K20/1000),0,VLOOKUP(F20,#REF!,6,0)*K20/1000) -> 0 | Q20: =IF(ISERROR(VLOOKUP(F20,#REF!,3,0)),0,VLOOKUP(F20,#REF!,3,0)) -> 0 | R20: =IF(ISERROR(VLOOKUP(F20,#REF!,4,0)),0,VLOOKUP(F20,#REF!,4,0)) -> 0 | S20: =IF(ISERROR(VLOOKUP(F20,#REF!,4,0)),0,VLOOKUP(F20,#REF!,10,0)/60*K20) -> 0
A21: =IF(C21=0,0,YEAR(C21)) -> 2019 | B21: =IF(C21>0,VLOOKUP(MONTH($C21),$AJ$3:$AK$14,2,0),0) -> SETEMBRO | C21: 43711 | E21: 2 | F21: 49 | H21: 455 | I21: 508 | K21: =SUM(G21:J21) -> 963 | L21: =IF(ISERROR(VLOOKUP($F21,#REF!,6,0)*G21/1000),0,VLOOKUP($F21,#REF!,6,0)*G21/1000) -> 0 | M21: =IF(ISERROR(VLOOKUP($F21,#REF!,6,0)*H21/1000),0,VLOOKUP($F21,#REF!,6,0)*H21/1000) -> 0 | N21: =IF(ISERROR(VLOOKUP($F21,#REF!,6,0)*I21/1000),0,VLOOKUP($F21,#REF!,6,0)*I21/1000) -> 0 | O21: =IF(ISERROR(VLOOKUP($F21,#REF!,6,0)*J21/1000),0,VLOOKUP($F21,#REF!,6,0)*J21/1000) -> 0 | P21: =IF(ISERROR(VLOOKUP(F21,#REF!,6,0)*K21/1000),0,VLOOKUP(F21,#REF!,6,0)*K21/1000) -> 0 | Q21: =IF(ISERROR(VLOOKUP(F21,#REF!,3,0)),0,VLOOKUP(F21,#REF!,3,0)) -> 0 | R21: =IF(ISERROR(VLOOKUP(F21,#REF!,4,0)),0,VLOOKUP(F21,#REF!,4,0)) -> 0 | S21: =IF(ISERROR(VLOOKUP(F21,#REF!,4,0)),0,VLOOKUP(F21,#REF!,10,0)/60*K21) -> 0
A22: =IF(C22=0,0,YEAR(C22)) -> 2019 | B22: =IF(C22>0,VLOOKUP(MONTH($C22),$AJ$3:$AK$14,2,0),0) -> SETEMBRO | C22: 43711 | E22: 2 | F22: 44 | H22: 279 | I22: 293 | K22: =SUM(G22:J22) -> 572 | L22: =IF(ISERROR(VLOOKUP($F22,#REF!,6,0)*G22/1000),0,VLOOKUP($F22,#REF!,6,0)*G22/1000) -> 0 | M22: =IF(ISERROR(VLOOKUP($F22,#REF!,6,0)*H22/1000),0,VLOOKUP($F22,#REF!,6,0)*H22/1000) -> 0 | N22: =IF(ISERROR(VLOOKUP($F22,#REF!,6,0)*I22/1000),0,VLOOKUP($F22,#REF!,6,0)*I22/1000) -> 0 | O22: =IF(ISERROR(VLOOKUP($F22,#REF!,6,0)*J22/1000),0,VLOOKUP($F22,#REF!,6,0)*J22/1000) -> 0 | P22: =IF(ISERROR(VLOOKUP(F22,#REF!,6,0)*K22/1000),0,VLOOKUP(F22,#REF!,6,0)*K22/1000) -> 0 | Q22: =IF(ISERROR(VLOOKUP(F22,#REF!,3,0)),0,VLOOKUP(F22,#REF!,3,0)) -> 0 | R22: =IF(ISERROR(VLOOKUP(F22,#REF!,4,0)),0,VLOOKUP(F22,#REF!,4,0)) -> 0 | S22: =IF(ISERROR(VLOOKUP(F22,#REF!,4,0)),0,VLOOKUP(F22,#REF!,10,0)/60*K22) -> 0
A23: =IF(C23=0,0,YEAR(C23)) -> 2019 | B23: =IF(C23>0,VLOOKUP(MONTH($C23),$AJ$3:$AK$14,2,0),0) -> SETEMBRO | C23: 43711 | E23: 2 | F23: 51 | G23: 628 | K23: =SUM(G23:J23) -> 628 | L23: =IF(ISERROR(VLOOKUP($F23,#REF!,6,0)*G23/1000),0,VLOOKUP($F23,#REF!,6,0)*G23/1000) -> 0 | M23: =IF(ISERROR(VLOOKUP($F23,#REF!,6,0)*H23/1000),0,VLOOKUP($F23,#REF!,6,0)*H23/1000) -> 0 | N23: =IF(ISERROR(VLOOKUP($F23,#REF!,6,0)*I23/1000),0,VLOOKUP($F23,#REF!,6,0)*I23/1000) -> 0 | O23: =IF(ISERROR(VLOOKUP($F23,#REF!,6,0)*J23/1000),0,VLOOKUP($F23,#REF!,6,0)*J23/1000) -> 0 | P23: =IF(ISERROR(VLOOKUP(F23,#REF!,6,0)*K23/1000),0,VLOOKUP(F23,#REF!,6,0)*K23/1000) -> 0 | Q23: =IF(ISERROR(VLOOKUP(F23,#REF!,3,0)),0,VLOOKUP(F23,#REF!,3,0)) -> 0 | R23: =IF(ISERROR(VLOOKUP(F23,#REF!,4,0)),0,VLOOKUP(F23,#REF!,4,0)) -> 0 | S23: =IF(ISERROR(VLOOKUP(F23,#REF!,4,0)),0,VLOOKUP(F23,#REF!,10,0)/60*K23) -> 0
A24: =IF(C24=0,0,YEAR(C24)) -> 2019 | B24: =IF(C24>0,VLOOKUP(MONTH($C24),$AJ$3:$AK$14,2,0),0) -> SETEMBRO | C24: 43711 | E24: 3 | F24: 3 | G24: 1060 | I24: 7 | J24: 90 | K24: =SUM(G24:J24) -> 1157 | L24: =IF(ISERROR(VLOOKUP($F24,#REF!,6,0)*G24/1000),0,VLOOKUP($F24,#REF!,6,0)*G24/1000) -> 0 | M24: =IF(ISERROR(VLOOKUP($F24,#REF!,6,0)*H24/1000),0,VLOOKUP($F24,#REF!,6,0)*H24/1000) -> 0 | N24: =IF(ISERROR(VLOOKUP($F24,#REF!,6,0)*I24/1000),0,VLOOKUP($F24,#REF!,6,0)*I24/1000) -> 0 | O24: =IF(ISERROR(VLOOKUP($F24,#REF!,6,0)*J24/1000),0,VLOOKUP($F24,#REF!,6,0)*J24/1000) -> 0 | P24: =IF(ISERROR(VLOOKUP(F24,#REF!,6,0)*K24/1000),0,VLOOKUP(F24,#REF!,6,0)*K24/1000) -> 0 | Q24: =IF(ISERROR(VLOOKUP(F24,#REF!,3,0)),0,VLOOKUP(F24,#REF!,3,0)) -> 0 | R24: =IF(ISERROR(VLOOKUP(F24,#REF!,4,0)),0,VLOOKUP(F24,#REF!,4,0)) -> 0 | S24: =IF(ISERROR(VLOOKUP(F24,#REF!,4,0)),0,VLOOKUP(F24,#REF!,10,0)/60*K24) -> 0
A25: =IF(C25=0,0,YEAR(C25)) -> 2019 | B25: =IF(C25>0,VLOOKUP(MONTH($C25),$AJ$3:$AK$14,2,0),0) -> SETEMBRO | C25: 43711 | E25: 3 | F25: 45 | G25: 1000 | I25: 90 | K25: =SUM(G25:J25) -> 1090 | L25: =IF(ISERROR(VLOOKUP($F25,#REF!,6,0)*G25/1000),0,VLOOKUP($F25,#REF!,6,0)*G25/1000) -> 0 | M25: =IF(ISERROR(VLOOKUP($F25,#REF!,6,0)*H25/1000),0,VLOOKUP($F25,#REF!,6,0)*H25/1000) -> 0 | N25: =IF(ISERROR(VLOOKUP($F25,#REF!,6,0)*I25/1000),0,VLOOKUP($F25,#REF!,6,0)*I25/1000) -> 0 | O25: =IF(ISERROR(VLOOKUP($F25,#REF!,6,0)*J25/1000),0,VLOOKUP($F25,#REF!,6,0)*J25/1000) -> 0 | P25: =IF(ISERROR(VLOOKUP(F25,#REF!,6,0)*K25/1000),0,VLOOKUP(F25,#REF!,6,0)*K25/1000) -> 0 | Q25: =IF(ISERROR(VLOOKUP(F25,#REF!,3,0)),0,VLOOKUP(F25,#REF!,3,0)) -> 0 | R25: =IF(ISERROR(VLOOKUP(F25,#REF!,4,0)),0,VLOOKUP(F25,#REF!,4,0)) -> 0 | S25: =IF(ISERROR(VLOOKUP(F25,#REF!,4,0)),0,VLOOKUP(F25,#REF!,10,0)/60*K25) -> 0
A26: =IF(C26=0,0,YEAR(C26)) -> 2019 | B26: =IF(C26>0,VLOOKUP(MONTH($C26),$AJ$3:$AK$14,2,0),0) -> SETEMBRO | C26: 43712 | E26: 1 | F26: 3 | G26: 432 | I26: 15 | K26: =SUM(G26:J26) -> 447 | L26: =IF(ISERROR(VLOOKUP($F26,#REF!,6,0)*G26/1000),0,VLOOKUP($F26,#REF!,6,0)*G26/1000) -> 0 | M26: =IF(ISERROR(VLOOKUP($F26,#REF!,6,0)*H26/1000),0,VLOOKUP($F26,#REF!,6,0)*H26/1000) -> 0 | N26: =IF(ISERROR(VLOOKUP($F26,#REF!,6,0)*I26/1000),0,VLOOKUP($F26,#REF!,6,0)*I26/1000) -> 0 | O26: =IF(ISERROR(VLOOKUP($F26,#REF!,6,0)*J26/1000),0,VLOOKUP($F26,#REF!,6,0)*J26/1000) -> 0 | P26: =IF(ISERROR(VLOOKUP(F26,#REF!,6,0)*K26/1000),0,VLOOKUP(F26,#REF!,6,0)*K26/1000) -> 0 | Q26: =IF(ISERROR(VLOOKUP(F26,#REF!,3,0)),0,VLOOKUP(F26,#REF!,3,0)) -> 0 | R26: =IF(ISERROR(VLOOKUP(F26,#REF!,4,0)),0,VLOOKUP(F26,#REF!,4,0)) -> 0 | S26: =IF(ISERROR(VLOOKUP(F26,#REF!,4,0)),0,VLOOKUP(F26,#REF!,10,0)/60*K26) -> 0
A27: =IF(C27=0,0,YEAR(C27)) -> 2019 | B27: =IF(C27>0,VLOOKUP(MONTH($C27),$AJ$3:$AK$14,2,0),0) -> SETEMBRO | C27: 43712 | E27: 1 | F27: 33 | G27: 576 | H27: 60 | I27: 20 | K27: =SUM(G27:J27) -> 656 | L27: =IF(ISERROR(VLOOKUP($F27,#REF!,6,0)*G27/1000),0,VLOOKUP($F27,#REF!,6,0)*G27/1000) -> 0 | M27: =IF(ISERROR(VLOOKUP($F27,#REF!,6,0)*H27/1000),0,VLOOKUP($F27,#REF!,6,0)*H27/1000) -> 0 | N27: =IF(ISERROR(VLOOKUP($F27,#REF!,6,0)*I27/1000),0,VLOOKUP($F27,#REF!,6,0)*I27/1000) -> 0 | O27: =IF(ISERROR(VLOOKUP($F27,#REF!,6,0)*J27/1000),0,VLOOKUP($F27,#REF!,6,0)*J27/1000) -> 0 | P27: =IF(ISERROR(VLOOKUP(F27,#REF!,6,0)*K27/1000),0,VLOOKUP(F27,#REF!,6,0)*K27/1000) -> 0 | Q27: =IF(ISERROR(VLOOKUP(F27,#REF!,3,0)),0,VLOOKUP(F27,#REF!,3,0)) -> 0 | R27: =IF(ISERROR(VLOOKUP(F27,#REF!,4,0)),0,VLOOKUP(F27,#REF!,4,0)) -> 0 | S27: =IF(ISERROR(VLOOKUP(F27,#REF!,4,0)),0,VLOOKUP(F27,#REF!,10,0)/60*K27) -> 0
A28: =IF(C28=0,0,YEAR(C28)) -> 2019 | B28: =IF(C28>0,VLOOKUP(MONTH($C28),$AJ$3:$AK$14,2,0),0) -> SETEMBRO | C28: 43712 | E28: 1 | F28: 32 | G28: 2482 | H28: 1350 | I28: 50 | K28: =SUM(G28:J28) -> 3882 | L28: =IF(ISERROR(VLOOKUP($F28,#REF!,6,0)*G28/1000),0,VLOOKUP($F28,#REF!,6,0)*G28/1000) -> 0 | M28: =IF(ISERROR(VLOOKUP($F28,#REF!,6,0)*H28/1000),0,VLOOKUP($F28,#REF!,6,0)*H28/1000) -> 0 | N28: =IF(ISERROR(VLOOKUP($F28,#REF!,6,0)*I28/1000),0,VLOOKUP($F28,#REF!,6,0)*I28/1000) -> 0 | O28: =IF(ISERROR(VLOOKUP($F28,#REF!,6,0)*J28/1000),0,VLOOKUP($F28,#REF!,6,0)*J28/1000) -> 0 | P28: =IF(ISERROR(VLOOKUP(F28,#REF!,6,0)*K28/1000),0,VLOOKUP(F28,#REF!,6,0)*K28/1000) -> 0 | Q28: =IF(ISERROR(VLOOKUP(F28,#REF!,3,0)),0,VLOOKUP(F28,#REF!,3,0)) -> 0 | R28: =IF(ISERROR(VLOOKUP(F28,#REF!,4,0)),0,VLOOKUP(F28,#REF!,4,0)) -> 0 | S28: =IF(ISERROR(VLOOKUP(F28,#REF!,4,0)),0,VLOOKUP(F28,#REF!,10,0)/60*K28) -> 0
A29: =IF(C29=0,0,YEAR(C29)) -> 2019 | B29: =IF(C29>0,VLOOKUP(MONTH($C29),$AJ$3:$AK$14,2,0),0) -> SETEMBRO | C29: 43712 | E29: 2 | F29: 32 | G29: 3120 | H29: 1250 | I29: 120 | K29: =SUM(G29:J29) -> 4490 | L29: =IF(ISERROR(VLOOKUP($F29,#REF!,6,0)*G29/1000),0,VLOOKUP($F29,#REF!,6,0)*G29/1000) -> 0 | M29: =IF(ISERROR(VLOOKUP($F29,#REF!,6,0)*H29/1000),0,VLOOKUP($F29,#REF!,6,0)*H29/1000) -> 0 | N29: =IF(ISERROR(VLOOKUP($F29,#REF!,6,0)*I29/1000),0,VLOOKUP($F29,#REF!,6,0)*I29/1000) -> 0 | O29: =IF(ISERROR(VLOOKUP($F29,#REF!,6,0)*J29/1000),0,VLOOKUP($F29,#REF!,6,0)*J29/1000) -> 0 | P29: =IF(ISERROR(VLOOKUP(F29,#REF!,6,0)*K29/1000),0,VLOOKUP(F29,#REF!,6,0)*K29/1000) -> 0 | Q29: =IF(ISERROR(VLOOKUP(F29,#REF!,3,0)),0,VLOOKUP(F29,#REF!,3,0)) -> 0 | R29: =IF(ISERROR(VLOOKUP(F29,#REF!,4,0)),0,VLOOKUP(F29,#REF!,4,0)) -> 0 | S29: =IF(ISERROR(VLOOKUP(F29,#REF!,4,0)),0,VLOOKUP(F29,#REF!,10,0)/60*K29) -> 0
A30: =IF(C30=0,0,YEAR(C30)) -> 2019 | B30: =IF(C30>0,VLOOKUP(MONTH($C30),$AJ$3:$AK$14,2,0),0) -> SETEMBRO | C30: 43712 | E30: 1 | F30: 50 | G30: 576 | K30: =SUM(G30:J30) -> 576 | L30: =IF(ISERROR(VLOOKUP($F30,#REF!,6,0)*G30/1000),0,VLOOKUP($F30,#REF!,6,0)*G30/1000) -> 0 | M30: =IF(ISERROR(VLOOKUP($F30,#REF!,6,0)*H30/1000),0,VLOOKUP($F30,#REF!,6,0)*H30/1000) -> 0 | N30: =IF(ISERROR(VLOOKUP($F30,#REF!,6,0)*I30/1000),0,VLOOKUP($F30,#REF!,6,0)*I30/1000) -> 0 | O30: =IF(ISERROR(VLOOKUP($F30,#REF!,6,0)*J30/1000),0,VLOOKUP($F30,#REF!,6,0)*J30/1000) -> 0 | P30: =IF(ISERROR(VLOOKUP(F30,#REF!,6,0)*K30/1000),0,VLOOKUP(F30,#REF!,6,0)*K30/1000) -> 0 | Q30: =IF(ISERROR(VLOOKUP(F30,#REF!,3,0)),0,VLOOKUP(F30,#REF!,3,0)) -> 0 | R30: =IF(ISERROR(VLOOKUP(F30,#REF!,4,0)),0,VLOOKUP(F30,#REF!,4,0)) -> 0 | S30: =IF(ISERROR(VLOOKUP(F30,#REF!,4,0)),0,VLOOKUP(F30,#REF!,10,0)/60*K30) -> 0
A31: =IF(C31=0,0,YEAR(C31)) -> 2019 | B31: =IF(C31>0,VLOOKUP(MONTH($C31),$AJ$3:$AK$14,2,0),0) -> SETEMBRO | C31: 43712 | E31: 1 | F31: 49 | G31: 422 | K31: =SUM(G31:J31) -> 422 | L31: =IF(ISERROR(VLOOKUP($F31,#REF!,6,0)*G31/1000),0,VLOOKUP($F31,#REF!,6,0)*G31/1000) -> 0 | M31: =IF(ISERROR(VLOOKUP($F31,#REF!,6,0)*H31/1000),0,VLOOKUP($F31,#REF!,6,0)*H31/1000) -> 0 | N31: =IF(ISERROR(VLOOKUP($F31,#REF!,6,0)*I31/1000),0,VLOOKUP($F31,#REF!,6,0)*I31/1000) -> 0 | O31: =IF(ISERROR(VLOOKUP($F31,#REF!,6,0)*J31/1000),0,VLOOKUP($F31,#REF!,6,0)*J31/1000) -> 0 | P31: =IF(ISERROR(VLOOKUP(F31,#REF!,6,0)*K31/1000),0,VLOOKUP(F31,#REF!,6,0)*K31/1000) -> 0 | Q31: =IF(ISERROR(VLOOKUP(F31,#REF!,3,0)),0,VLOOKUP(F31,#REF!,3,0)) -> 0 | R31: =IF(ISERROR(VLOOKUP(F31,#REF!,4,0)),0,VLOOKUP(F31,#REF!,4,0)) -> 0 | S31: =IF(ISERROR(VLOOKUP(F31,#REF!,4,0)),0,VLOOKUP(F31,#REF!,10,0)/60*K31) -> 0
A32: =IF(C32=0,0,YEAR(C32)) -> 2019 | B32: =IF(C32>0,VLOOKUP(MONTH($C32),$AJ$3:$AK$14,2,0),0) -> SETEMBRO | C32: 43712 | E32: 1 | F32: 51 | G32: 650 | H32: 498 | I32: 45 | K32: =SUM(G32:J32) -> 1193 | L32: =IF(ISERROR(VLOOKUP($F32,#REF!,6,0)*G32/1000),0,VLOOKUP($F32,#REF!,6,0)*G32/1000) -> 0 | M32: =IF(ISERROR(VLOOKUP($F32,#REF!,6,0)*H32/1000),0,VLOOKUP($F32,#REF!,6,0)*H32/1000) -> 0 | N32: =IF(ISERROR(VLOOKUP($F32,#REF!,6,0)*I32/1000),0,VLOOKUP($F32,#REF!,6,0)*I32/1000) -> 0 | O32: =IF(ISERROR(VLOOKUP($F32,#REF!,6,0)*J32/1000),0,VLOOKUP($F32,#REF!,6,0)*J32/1000) -> 0 | P32: =IF(ISERROR(VLOOKUP(F32,#REF!,6,0)*K32/1000),0,VLOOKUP(F32,#REF!,6,0)*K32/1000) -> 0 | Q32: =IF(ISERROR(VLOOKUP(F32,#REF!,3,0)),0,VLOOKUP(F32,#REF!,3,0)) -> 0 | R32: =IF(ISERROR(VLOOKUP(F32,#REF!,4,0)),0,VLOOKUP(F32,#REF!,4,0)) -> 0 | S32: =IF(ISERROR(VLOOKUP(F32,#REF!,4,0)),0,VLOOKUP(F32,#REF!,10,0)/60*K32) -> 0
A33: =IF(C33=0,0,YEAR(C33)) -> 2019 | B33: =IF(C33>0,VLOOKUP(MONTH($C33),$AJ$3:$AK$14,2,0),0) -> SETEMBRO | C33: 43712 | E33: 1 | F33: 12 | G33: 818 | K33: =SUM(G33:J33) -> 818 | L33: =IF(ISERROR(VLOOKUP($F33,#REF!,6,0)*G33/1000),0,VLOOKUP($F33,#REF!,6,0)*G33/1000) -> 0 | M33: =IF(ISERROR(VLOOKUP($F33,#REF!,6,0)*H33/1000),0,VLOOKUP($F33,#REF!,6,0)*H33/1000) -> 0 | N33: =IF(ISERROR(VLOOKUP($F33,#REF!,6,0)*I33/1000),0,VLOOKUP($F33,#REF!,6,0)*I33/1000) -> 0 | O33: =IF(ISERROR(VLOOKUP($F33,#REF!,6,0)*J33/1000),0,VLOOKUP($F33,#REF!,6,0)*J33/1000) -> 0 | P33: =IF(ISERROR(VLOOKUP(F33,#REF!,6,0)*K33/1000),0,VLOOKUP(F33,#REF!,6,0)*K33/1000) -> 0 | Q33: =IF(ISERROR(VLOOKUP(F33,#REF!,3,0)),0,VLOOKUP(F33,#REF!,3,0)) -> 0 | R33: =IF(ISERROR(VLOOKUP(F33,#REF!,4,0)),0,VLOOKUP(F33,#REF!,4,0)) -> 0 | S33: =IF(ISERROR(VLOOKUP(F33,#REF!,4,0)),0,VLOOKUP(F33,#REF!,10,0)/60*K33) -> 0
A34: =IF(C34=0,0,YEAR(C34)) -> 2019 | B34: =IF(C34>0,VLOOKUP(MONTH($C34),$AJ$3:$AK$14,2,0),0) -> SETEMBRO | C34: 43712 | E34: 2 | F34: 50 | G34: 584 | H34: 501 | K34: =SUM(G34:J34) -> 1085 | L34: =IF(ISERROR(VLOOKUP($F34,#REF!,6,0)*G34/1000),0,VLOOKUP($F34,#REF!,6,0)*G34/1000) -> 0 | M34: =IF(ISERROR(VLOOKUP($F34,#REF!,6,0)*H34/1000),0,VLOOKUP($F34,#REF!,6,0)*H34/1000) -> 0 | N34: =IF(ISERROR(VLOOKUP($F34,#REF!,6,0)*I34/1000),0,VLOOKUP($F34,#REF!,6,0)*I34/1000) -> 0 | O34: =IF(ISERROR(VLOOKUP($F34,#REF!,6,0)*J34/1000),0,VLOOKUP($F34,#REF!,6,0)*J34/1000) -> 0 | P34: =IF(ISERROR(VLOOKUP(F34,#REF!,6,0)*K34/1000),0,VLOOKUP(F34,#REF!,6,0)*K34/1000) -> 0 | Q34: =IF(ISERROR(VLOOKUP(F34,#REF!,3,0)),0,VLOOKUP(F34,#REF!,3,0)) -> 0 | R34: =IF(ISERROR(VLOOKUP(F34,#REF!,4,0)),0,VLOOKUP(F34,#REF!,4,0)) -> 0 | S34: =IF(ISERROR(VLOOKUP(F34,#REF!,4,0)),0,VLOOKUP(F34,#REF!,10,0)/60*K34) -> 0
A35: =IF(C35=0,0,YEAR(C35)) -> 2019 | B35: =IF(C35>0,VLOOKUP(MONTH($C35),$AJ$3:$AK$14,2,0),0) -> SETEMBRO | C35: 43712 | E35: 2 | F35: 49 | G35: 441 | H35: 461 | I35: 483 | K35: =SUM(G35:J35) -> 1385 | L35: =IF(ISERROR(VLOOKUP($F35,#REF!,6,0)*G35/1000),0,VLOOKUP($F35,#REF!,6,0)*G35/1000) -> 0 | M35: =IF(ISERROR(VLOOKUP($F35,#REF!,6,0)*H35/1000),0,VLOOKUP($F35,#REF!,6,0)*H35/1000) -> 0 | N35: =IF(ISERROR(VLOOKUP($F35,#REF!,6,0)*I35/1000),0,VLOOKUP($F35,#REF!,6,0)*I35/1000) -> 0 | O35: =IF(ISERROR(VLOOKUP($F35,#REF!,6,0)*J35/1000),0,VLOOKUP($F35,#REF!,6,0)*J35/1000) -> 0 | P35: =IF(ISERROR(VLOOKUP(F35,#REF!,6,0)*K35/1000),0,VLOOKUP(F35,#REF!,6,0)*K35/1000) -> 0 | Q35: =IF(ISERROR(VLOOKUP(F35,#REF!,3,0)),0,VLOOKUP(F35,#REF!,3,0)) -> 0 | R35: =IF(ISERROR(VLOOKUP(F35,#REF!,4,0)),0,VLOOKUP(F35,#REF!,4,0)) -> 0 | S35: =IF(ISERROR(VLOOKUP(F35,#REF!,4,0)),0,VLOOKUP(F35,#REF!,10,0)/60*K35) -> 0
A36: =IF(C36=0,0,YEAR(C36)) -> 2019 | B36: =IF(C36>0,VLOOKUP(MONTH($C36),$AJ$3:$AK$14,2,0),0) -> SETEMBRO | C36: 43712 | E36: 2 | F36: 51 | G36: 688 | H36: 700 | K36: =SUM(G36:J36) -> 1388 | L36: =IF(ISERROR(VLOOKUP($F36,#REF!,6,0)*G36/1000),0,VLOOKUP($F36,#REF!,6,0)*G36/1000) -> 0 | M36: =IF(ISERROR(VLOOKUP($F36,#REF!,6,0)*H36/1000),0,VLOOKUP($F36,#REF!,6,0)*H36/1000) -> 0 | N36: =IF(ISERROR(VLOOKUP($F36,#REF!,6,0)*I36/1000),0,VLOOKUP($F36,#REF!,6,0)*I36/1000) -> 0 | O36: =IF(ISERROR(VLOOKUP($F36,#REF!,6,0)*J36/1000),0,VLOOKUP($F36,#REF!,6,0)*J36/1000) -> 0 | P36: =IF(ISERROR(VLOOKUP(F36,#REF!,6,0)*K36/1000),0,VLOOKUP(F36,#REF!,6,0)*K36/1000) -> 0 | Q36: =IF(ISERROR(VLOOKUP(F36,#REF!,3,0)),0,VLOOKUP(F36,#REF!,3,0)) -> 0 | R36: =IF(ISERROR(VLOOKUP(F36,#REF!,4,0)),0,VLOOKUP(F36,#REF!,4,0)) -> 0 | S36: =IF(ISERROR(VLOOKUP(F36,#REF!,4,0)),0,VLOOKUP(F36,#REF!,10,0)/60*K36) -> 0
A37: =IF(C37=0,0,YEAR(C37)) -> 2019 | B37: =IF(C37>0,VLOOKUP(MONTH($C37),$AJ$3:$AK$14,2,0),0) -> SETEMBRO | C37: 43712 | E37: 3 | F37: 32 | G37: 4800 | H37: 150 | I37: 145 | J37: 50 | K37: =SUM(G37:J37) -> 5145 | L37: =IF(ISERROR(VLOOKUP($F37,#REF!,6,0)*G37/1000),0,VLOOKUP($F37,#REF!,6,0)*G37/1000) -> 0 | M37: =IF(ISERROR(VLOOKUP($F37,#REF!,6,0)*H37/1000),0,VLOOKUP($F37,#REF!,6,0)*H37/1000) -> 0 | N37: =IF(ISERROR(VLOOKUP($F37,#REF!,6,0)*I37/1000),0,VLOOKUP($F37,#REF!,6,0)*I37/1000) -> 0 | O37: =IF(ISERROR(VLOOKUP($F37,#REF!,6,0)*J37/1000),0,VLOOKUP($F37,#REF!,6,0)*J37/1000) -> 0 | P37: =IF(ISERROR(VLOOKUP(F37,#REF!,6,0)*K37/1000),0,VLOOKUP(F37,#REF!,6,0)*K37/1000) -> 0 | Q37: =IF(ISERROR(VLOOKUP(F37,#REF!,3,0)),0,VLOOKUP(F37,#REF!,3,0)) -> 0 | R37: =IF(ISERROR(VLOOKUP(F37,#REF!,4,0)),0,VLOOKUP(F37,#REF!,4,0)) -> 0 | S37: =IF(ISERROR(VLOOKUP(F37,#REF!,4,0)),0,VLOOKUP(F37,#REF!,10,0)/60*K37) -> 0
A38: =IF(C38=0,0,YEAR(C38)) -> 2019 | B38: =IF(C38>0,VLOOKUP(MONTH($C38),$AJ$3:$AK$14,2,0),0) -> SETEMBRO | C38: 43712 | E38: 3 | F38: 3 | G38: 424 | I38: 18 | J38: 70 | K38: =SUM(G38:J38) -> 512 | L38: =IF(ISERROR(VLOOKUP($F38,#REF!,6,0)*G38/1000),0,VLOOKUP($F38,#REF!,6,0)*G38/1000) -> 0 | M38: =IF(ISERROR(VLOOKUP($F38,#REF!,6,0)*H38/1000),0,VLOOKUP($F38,#REF!,6,0)*H38/1000) -> 0 | N38: =IF(ISERROR(VLOOKUP($F38,#REF!,6,0)*I38/1000),0,VLOOKUP($F38,#REF!,6,0)*I38/1000) -> 0 | O38: =IF(ISERROR(VLOOKUP($F38,#REF!,6,0)*J38/1000),0,VLOOKUP($F38,#REF!,6,0)*J38/1000) -> 0 | P38: =IF(ISERROR(VLOOKUP(F38,#REF!,6,0)*K38/1000),0,VLOOKUP(F38,#REF!,6,0)*K38/1000) -> 0 | Q38: =IF(ISERROR(VLOOKUP(F38,#REF!,3,0)),0,VLOOKUP(F38,#REF!,3,0)) -> 0 | R38: =IF(ISERROR(VLOOKUP(F38,#REF!,4,0)),0,VLOOKUP(F38,#REF!,4,0)) -> 0 | S38: =IF(ISERROR(VLOOKUP(F38,#REF!,4,0)),0,VLOOKUP(F38,#REF!,10,0)/60*K38) -> 0
A39: =IF(C39=0,0,YEAR(C39)) -> 2019 | B39: =IF(C39>0,VLOOKUP(MONTH($C39),$AJ$3:$AK$14,2,0),0) -> SETEMBRO | C39: 43713 | E39: 1 | F39: 32 | G39: 2145 | H39: 650 | I39: 45 | J39: 300 | K39: =SUM(G39:J39) -> 3140 | L39: =IF(ISERROR(VLOOKUP($F39,#REF!,6,0)*G39/1000),0,VLOOKUP($F39,#REF!,6,0)*G39/1000) -> 0 | M39: =IF(ISERROR(VLOOKUP($F39,#REF!,6,0)*H39/1000),0,VLOOKUP($F39,#REF!,6,0)*H39/1000) -> 0 | N39: =IF(ISERROR(VLOOKUP($F39,#REF!,6,0)*I39/1000),0,VLOOKUP($F39,#REF!,6,0)*I39/1000) -> 0 | O39: =IF(ISERROR(VLOOKUP($F39,#REF!,6,0)*J39/1000),0,VLOOKUP($F39,#REF!,6,0)*J39/1000) -> 0 | P39: =IF(ISERROR(VLOOKUP(F39,#REF!,6,0)*K39/1000),0,VLOOKUP(F39,#REF!,6,0)*K39/1000) -> 0 | Q39: =IF(ISERROR(VLOOKUP(F39,#REF!,3,0)),0,VLOOKUP(F39,#REF!,3,0)) -> 0 | R39: =IF(ISERROR(VLOOKUP(F39,#REF!,4,0)),0,VLOOKUP(F39,#REF!,4,0)) -> 0 | S39: =IF(ISERROR(VLOOKUP(F39,#REF!,4,0)),0,VLOOKUP(F39,#REF!,10,0)/60*K39) -> 0
A40: =IF(C40=0,0,YEAR(C40)) -> 2019 | B40: =IF(C40>0,VLOOKUP(MONTH($C40),$AJ$3:$AK$14,2,0),0) -> SETEMBRO | C40: 43713 | E40: 1 | F40: 3 | G40: 432 | I40: 3 | K40: =SUM(G40:J40) -> 435 | L40: =IF(ISERROR(VLOOKUP($F40,#REF!,6,0)*G40/1000),0,VLOOKUP($F40,#REF!,6,0)*G40/1000) -> 0 | M40: =IF(ISERROR(VLOOKUP($F40,#REF!,6,0)*H40/1000),0,VLOOKUP($F40,#REF!,6,0)*H40/1000) -> 0 | N40: =IF(ISERROR(VLOOKUP($F40,#REF!,6,0)*I40/1000),0,VLOOKUP($F40,#REF!,6,0)*I40/1000) -> 0 | O40: =IF(ISERROR(VLOOKUP($F40,#REF!,6,0)*J40/1000),0,VLOOKUP($F40,#REF!,6,0)*J40/1000) -> 0 | P40: =IF(ISERROR(VLOOKUP(F40,#REF!,6,0)*K40/1000),0,VLOOKUP(F40,#REF!,6,0)*K40/1000) -> 0 | Q40: =IF(ISERROR(VLOOKUP(F40,#REF!,3,0)),0,VLOOKUP(F40,#REF!,3,0)) -> 0 | R40: =IF(ISERROR(VLOOKUP(F40,#REF!,4,0)),0,VLOOKUP(F40,#REF!,4,0)) -> 0 | S40: =IF(ISERROR(VLOOKUP(F40,#REF!,4,0)),0,VLOOKUP(F40,#REF!,10,0)/60*K40) -> 0
...

Sheet HOMEM X HORA
E1: PLANEJAMENTO DE TRABALHO | N1: TEMPO DISPONÍVEL PLANEJADO HOMEM X HORA
A2: ANO | B2: MÊS | C2: DIA DA SEMANA | D2: DATA | E2: QTD POSTOS DE TRABALHO P/ ACABAMENTO LINHA 1 | I2: QTD POSTOS DE TRABALHO P/ ACABAMENTO LINHA 2 | L2: TOTAL | N2: HOMEM / HORA PLANEJADO LINHA 1 | Q2: HOMEM / HORA PLANEJADO LINHA 2 | T2: TOTAL | U2: Meta Homem Hora ativa | AE2: 1 | AF2: DOMINGO | AG2: 1 | AH2: JANEIRO
E3: NOITE | F3: DIA | G3: TARDE | I3: NOITE | J3: DIA | K3: TARDE | N3: NOITE | O3: DIA | P3: TARDE | Q3: NOITE | R3: DIA | S3: TARDE | AE3: 2 | AF3: SEGUNDA | AG3: 2 | AH3: FEVEREIRO
A5: =YEAR(D5) -> 2022 | C5: =VLOOKUP(WEEKDAY(D5),$AE$2:$AF$9,2,0) -> QUARTA | D5: 44853 | E5: =IF(WEEKDAY($D5)<2,0,IF(WEEKDAY($D5)>6,0,7)) -> 7 | F5: =IF(WEEKDAY($D5)<2,0,IF(WEEKDAY($D5)>7,0,7)) -> 7 | H5: =SUM(E5:G5) -> 14 | I5: =IF(WEEKDAY($D5)<2,0,IF(WEEKDAY($D5)>6,0,8)) -> 8 | J5: =IF(WEEKDAY($D5)<2,0,IF(WEEKDAY($D5)>7,0,8)) -> 8 | K5: =IF(WEEKDAY($D5)<2,0,IF(WEEKDAY($D5)>6,0,8)) -> 8 | L5: =SUM(I5:K5) -> 24 | N5: =E5*7.48 -> 52.36 | O5: =F5*6 -> 42 | P5: =G5*8.5 -> 0 | Q5: =I5*7.48 -> 59.84 | R5: =J5*6 -> 48 | S5: =K5*8.5 -> 68 | T5: =SUM(N5:S5) -> 270.2 | U5: =T5*0.8 -> 216.16 | AE5: 3 | AF5: TERÇA | AG5: 3 | AH5: MARÇO
A6: =YEAR(D6) -> 2022 | C6: =VLOOKUP(WEEKDAY(D6),$AE$2:$AF$9,2,0) -> QUINTA | D6: 44854 | E6: =IF(WEEKDAY($D6)<2,0,IF(WEEKDAY($D6)>6,0,7)) -> 7 | F6: =IF(WEEKDAY($D6)<2,0,IF(WEEKDAY($D6)>7,0,7)) -> 7 | H6: =SUM(E6:G6) -> 14 | I6: =IF(WEEKDAY($D6)<2,0,IF(WEEKDAY($D6)>6,0,8)) -> 8 | J6: =IF(WEEKDAY($D6)<2,0,IF(WEEKDAY($D6)>7,0,8)) -> 8 | K6: =IF(WEEKDAY($D6)<2,0,IF(WEEKDAY($D6)>6,0,8)) -> 8 | L6: =SUM(I6:K6) -> 24 | N6: =E6*7.48 -> 52.36 | O6: =F6*6 -> 42 | P6: =G6*8.5 -> 0 | Q6: =I6*7.48 -> 59.84 | R6: =J6*6 -> 48 | S6: =K6*8.5 -> 68 | T6: =SUM(N6:S6) -> 270.2 | U6: =T6*0.8 -> 216.16 | AE6: 4 | AF6: QUARTA | AG6: 4 | AH6: ABRIL
A7: =YEAR(D7) -> 2022 | C7: =VLOOKUP(WEEKDAY(D7),$AE$2:$AF$9,2,0) -> SEXTA | D7: 44855 | E7: =IF(WEEKDAY($D7)<2,0,IF(WEEKDAY($D7)>6,0,7)) -> 7 | F7: =IF(WEEKDAY($D7)<2,0,IF(WEEKDAY($D7)>7,0,7)) -> 7 | H7: =SUM(E7:G7) -> 14 | I7: =IF(WEEKDAY($D7)<2,0,IF(WEEKDAY($D7)>6,0,8)) -> 8 | J7: =IF(WEEKDAY($D7)<2,0,IF(WEEKDAY($D7)>7,0,8)) -> 8 | K7: =IF(WEEKDAY($D7)<2,0,IF(WEEKDAY($D7)>6,0,8)) -> 8 | L7: =SUM(I7:K7) -> 24 | N7: =E7*7.48 -> 52.36 | O7: =F7*6 -> 42 | P7: =G7*8.5 -> 0 | Q7: =I7*7.48 -> 59.84 | R7: =J7*6 -> 48 | S7: =K7*8.5 -> 68 | T7: =SUM(N7:S7) -> 270.2 | U7: =T7*0.8 -> 216.16 | AE7: 5 | AF7: QUINTA | AG7: 5 | AH7: MAIO
A8: =YEAR(D8) -> 2022 | C8: =VLOOKUP(WEEKDAY(D8),$AE$2:$AF$9,2,0) -> SÁBADO | D8: 44856 | E8: =IF(WEEKDAY($D8)<2,0,IF(WEEKDAY($D8)>6,0,7)) -> 0 | F8: =IF(WEEKDAY($D8)<2,0,IF(WEEKDAY($D8)>7,0,7)) -> 7 | H8: =SUM(E8:G8) -> 7 | I8: =IF(WEEKDAY($D8)<2,0,IF(WEEKDAY($D8)>6,0,8)) -> 0 | J8: =IF(WEEKDAY($D8)<2,0,IF(WEEKDAY($D8)>7,0,8)) -> 8 | K8: =IF(WEEKDAY($D8)<2,0,IF(WEEKDAY($D8)>6,0,8)) -> 0 | L8: =SUM(I8:K8) -> 8 | N8: =E8*7.48 -> 0 | O8: =F8*6 -> 42 | P8: =G8*8.5 -> 0 | Q8: =I8*7.48 -> 0 | R8: =J8*6 -> 48 | S8: =K8*8.5 -> 0 | T8: =SUM(N8:S8) -> 90 | U8: =T8*0.8 -> 72 | AE8: 6 | AF8: SEXTA | AG8: 6 | AH8: JUNHO
A9: =YEAR(D9) -> 2022 | C9: =VLOOKUP(WEEKDAY(D9),$AE$2:$AF$9,2,0) -> DOMINGO | D9: 44857 | E9: =IF(WEEKDAY($D9)<2,0,IF(WEEKDAY($D9)>6,0,7)) -> 0 | F9: =IF(WEEKDAY($D9)<2,0,IF(WEEKDAY($D9)>7,0,7)) -> 0 | H9: =SUM(E9:G9) -> 0 | I9: =IF(WEEKDAY($D9)<2,0,IF(WEEKDAY($D9)>6,0,8)) -> 0 | J9: =IF(WEEKDAY($D9)<2,0,IF(WEEKDAY($D9)>7,0,8)) -> 0 | K9: =IF(WEEKDAY($D9)<2,0,IF(WEEKDAY($D9)>6,0,8)) -> 0 | L9: =SUM(I9:K9) -> 0 | N9: =E9*7.48 -> 0 | O9: =F9*6 -> 0 | P9: =G9*8.5 -> 0 | Q9: =I9*7.48 -> 0 | R9: =J9*6 -> 0 | S9: =K9*8.5 -> 0 | T9: =SUM(N9:S9) -> 0 | U9: =T9*0.8 -> 0 | AE9: 7 | AF9: SÁBADO | AG9: 7 | AH9: JULHO
A10: =YEAR(D10) -> 2022 | C10: =VLOOKUP(WEEKDAY(D10),$AE$2:$AF$9,2,0) -> SEGUNDA | D10: 44858 | E10: =IF(WEEKDAY($D10)<2,0,IF(WEEKDAY($D10)>6,0,7)) -> 7 | F10: =IF(WEEKDAY($D10)<2,0,IF(WEEKDAY($D10)>7,0,7)) -> 7 | H10: =SUM(E10:G10) -> 14 | I10: =IF(WEEKDAY($D10)<2,0,IF(WEEKDAY($D10)>6,0,8)) -> 8 | J10: =IF(WEEKDAY($D10)<2,0,IF(WEEKDAY($D10)>7,0,8)) -> 8 | K10: =IF(WEEKDAY($D10)<2,0,IF(WEEKDAY($D10)>6,0,8)) -> 8 | L10: =SUM(I10:K10) -> 24 | N10: =E10*7.48 -> 52.36 | O10: =F10*6 -> 42 | P10: =G10*8.5 -> 0 | Q10: =I10*7.48 -> 59.84 | R10: =J10*6 -> 48 | S10: =K10*8.5 -> 68 | T10: =SUM(N10:S10) -> 270.2 | U10: =T10*0.8 -> 216.16 | AG10: 8 | AH10: AGOSTO
A11: =YEAR(D11) -> 2022 | C11: =VLOOKUP(WEEKDAY(D11),$AE$2:$AF$9,2,0) -> TERÇA | D11: 44859 | E11: =IF(WEEKDAY($D11)<2,0,IF(WEEKDAY($D11)>6,0,7)) -> 7 | F11: =IF(WEEKDAY($D11)<2,0,IF(WEEKDAY($D11)>7,0,7)) -> 7 | H11: =SUM(E11:G11) -> 14 | I11: =IF(WEEKDAY($D11)<2,0,IF(WEEKDAY($D11)>6,0,8)) -> 8 | J11: =IF(WEEKDAY($D11)<2,0,IF(WEEKDAY($D11)>7,0,8)) -> 8 | K11: =IF(WEEKDAY($D11)<2,0,IF(WEEKDAY($D11)>6,0,8)) -> 8 | L11: =SUM(I11:K11) -> 24 | N11: =E11*7.48 -> 52.36 | O11: =F11*6 -> 42 | P11: =G11*8.5 -> 0 | Q11: =I11*7.48 -> 59.84 | R11: =J11*6 -> 48 | S11: =K11*8.5 -> 68 | T11: =SUM(N11:S11) -> 270.2 | U11: =T11*0.8 -> 216.16 | AG11: 9 | AH11: SETEMBRO
A12: =YEAR(D12) -> 2022 | C12: =VLOOKUP(WEEKDAY(D12),$AE$2:$AF$9,2,0) -> QUARTA | D12: 44860 | E12: =IF(WEEKDAY($D12)<2,0,IF(WEEKDAY($D12)>6,0,7)) -> 7 | F12: =IF(WEEKDAY($D12)<2,0,IF(WEEKDAY($D12)>7,0,7)) -> 7 | H12: =SUM(E12:G12) -> 14 | I12: =IF(WEEKDAY($D12)<2,0,IF(WEEKDAY($D12)>6,0,8)) -> 8 | J12: =IF(WEEKDAY($D12)<2,0,IF(WEEKDAY($D12)>7,0,8)) -> 8 | K12: =IF(WEEKDAY($D12)<2,0,IF(WEEKDAY($D12)>6,0,8)) -> 8 | L12: =SUM(I12:K12) -> 24 | N12: =E12*7.48 -> 52.36 | O12: =F12*6 -> 42 | P12: =G12*8.5 -> 0 | Q12: =I12*7.48 -> 59.84 | R12: =J12*6 -> 48 | S12: =K12*8.5 -> 68 | T12: =SUM(N12:S12) -> 270.2 | U12: =T12*0.8 -> 216.16 | AG12: 10 | AH12: OUTUBRO
A13: =YEAR(D13) -> 2022 | C13: =VLOOKUP(WEEKDAY(D13),$AE$2:$AF$9,2,0) -> QUINTA | D13: 44861 | E13: =IF(WEEKDAY($D13)<2,0,IF(WEEKDAY($D13)>6,0,7)) -> 7 | F13: =IF(WEEKDAY($D13)<2,0,IF(WEEKDAY($D13)>7,0,7)) -> 7 | H13: =SUM(E13:G13) -> 14 | I13: =IF(WEEKDAY($D13)<2,0,IF(WEEKDAY($D13)>6,0,8)) -> 8 | J13: =IF(WEEKDAY($D13)<2,0,IF(WEEKDAY($D13)>7,0,8)) -> 8 | K13: =IF(WEEKDAY($D13)<2,0,IF(WEEKDAY($D13)>6,0,8)) -> 8 | L13: =SUM(I13:K13) -> 24 | N13: =E13*7.48 -> 52.36 | O13: =F13*6 -> 42 | P13: =G13*8.5 -> 0 | Q13: =I13*7.48 -> 59.84 | R13: =J13*6 -> 48 | S13: =K13*8.5 -> 68 | T13: =SUM(N13:S13) -> 270.2 | U13: =T13*0.8 -> 216.16 | AG13: 11 | AH13: NOVEMBRO
A14: =YEAR(D14) -> 2022 | C14: =VLOOKUP(WEEKDAY(D14),$AE$2:$AF$9,2,0) -> SEXTA | D14: 44862 | E14: =IF(WEEKDAY($D14)<2,0,IF(WEEKDAY($D14)>6,0,7)) -> 7 | F14: =IF(WEEKDAY($D14)<2,0,IF(WEEKDAY($D14)>7,0,7)) -> 7 | H14: =SUM(E14:G14) -> 14 | I14: =IF(WEEKDAY($D14)<2,0,IF(WEEKDAY($D14)>6,0,8)) -> 8 | J14: =IF(WEEKDAY($D14)<2,0,IF(WEEKDAY($D14)>7,0,8)) -> 8 | K14: =IF(WEEKDAY($D14)<2,0,IF(WEEKDAY($D14)>6,0,8)) -> 8 | L14: =SUM(I14:K14) -> 24 | N14: =E14*7.48 -> 52.36 | O14: =F14*6 -> 42 | P14: =G14*8.5 -> 0 | Q14: =I14*7.48 -> 59.84 | R14: =J14*6 -> 48 | S14: =K14*8.5 -> 68 | T14: =SUM(N14:S14) -> 270.2 | U14: =T14*0.8 -> 216.16 | AG14: 12 | AH14: DEZEMBRO
A15: =YEAR(D15) -> 2022 | C15: =VLOOKUP(WEEKDAY(D15),$AE$2:$AF$9,2,0) -> SÁBADO | D15: 44863 | E15: =IF(WEEKDAY($D15)<2,0,IF(WEEKDAY($D15)>6,0,7)) -> 0 | F15: =IF(WEEKDAY($D15)<2,0,IF(WEEKDAY($D15)>7,0,7)) -> 7 | H15: =SUM(E15:G15) -> 7 | I15: =IF(WEEKDAY($D15)<2,0,IF(WEEKDAY($D15)>6,0,8)) -> 0 | J15: =IF(WEEKDAY($D15)<2,0,IF(WEEKDAY($D15)>7,0,8)) -> 8 | K15: =IF(WEEKDAY($D15)<2,0,IF(WEEKDAY($D15)>6,0,8)) -> 0 | L15: =SUM(I15:K15) -> 8 | N15: =E15*7.48 -> 0 | O15: =F15*6 -> 42 | P15: =G15*8.5 -> 0 | Q15: =I15*7.48 -> 0 | R15: =J15*6 -> 48 | S15: =K15*8.5 -> 0 | T15: =SUM(N15:S15) -> 90 | U15: =T15*0.8 -> 72
A16: =YEAR(D16) -> 2022 | C16: =VLOOKUP(WEEKDAY(D16),$AE$2:$AF$9,2,0) -> DOMINGO | D16: 44864 | E16: =IF(WEEKDAY($D16)<2,0,IF(WEEKDAY($D16)>6,0,7)) -> 0 | F16: =IF(WEEKDAY($D16)<2,0,IF(WEEKDAY($D16)>7,0,7)) -> 0 | H16: =SUM(E16:G16) -> 0 | I16: =IF(WEEKDAY($D16)<2,0,IF(WEEKDAY($D16)>6,0,8)) -> 0 | J16: =IF(WEEKDAY($D16)<2,0,IF(WEEKDAY($D16)>7,0,8)) -> 0 | K16: =IF(WEEKDAY($D16)<2,0,IF(WEEKDAY($D16)>6,0,8)) -> 0 | L16: =SUM(I16:K16) -> 0 | N16: =E16*7.48 -> 0 | O16: =F16*6 -> 0 | P16: =G16*8.5 -> 0 | Q16: =I16*7.48 -> 0 | R16: =J16*6 -> 0 | S16: =K16*8.5 -> 0 | T16: =SUM(N16:S16) -> 0 | U16: =T16*0.8 -> 0
A17: =YEAR(D17) -> 2022 | C17: =VLOOKUP(WEEKDAY(D17),$AE$2:$AF$9,2,0) -> SEGUNDA | D17: 44865 | E17: =IF(WEEKDAY($D17)<2,0,IF(WEEKDAY($D17)>6,0,7)) -> 7 | F17: =IF(WEEKDAY($D17)<2,0,IF(WEEKDAY($D17)>7,0,7)) -> 7 | H17: =SUM(E17:G17) -> 14 | I17: =IF(WEEKDAY($D17)<2,0,IF(WEEKDAY($D17)>6,0,8)) -> 8 | J17: =IF(WEEKDAY($D17)<2,0,IF(WEEKDAY($D17)>7,0,8)) -> 8 | K17: =IF(WEEKDAY($D17)<2,0,IF(WEEKDAY($D17)>6,0,8)) -> 8 | L17: =SUM(I17:K17) -> 24 | N17: =E17*7.48 -> 52.36 | O17: =F17*6 -> 42 | P17: =G17*8.5 -> 0 | Q17: =I17*7.48 -> 59.84 | R17: =J17*6 -> 48 | S17: =K17*8.5 -> 68 | T17: =SUM(N17:S17) -> 270.2 | U17: =T17*0.8 -> 216.16
A18: =YEAR(D18) -> 2022 | C18: =VLOOKUP(WEEKDAY(D18),$AE$2:$AF$9,2,0) -> TERÇA | D18: 44866 | E18: =IF(WEEKDAY($D18)<2,0,IF(WEEKDAY($D18)>6,0,7)) -> 7 | F18: =IF(WEEKDAY($D18)<2,0,IF(WEEKDAY($D18)>7,0,7)) -> 7 | H18: =SUM(E18:G18) -> 14 | I18: =IF(WEEKDAY($D18)<2,0,IF(WEEKDAY($D18)>6,0,8)) -> 8 | J18: =IF(WEEKDAY($D18)<2,0,IF(WEEKDAY($D18)>7,0,8)) -> 8 | K18: =IF(WEEKDAY($D18)<2,0,IF(WEEKDAY($D18)>6,0,8)) -> 8 | L18: =SUM(I18:K18) -> 24 | N18: =E18*7.48 -> 52.36 | O18: =F18*6 -> 42 | P18: =G18*8.5 -> 0 | Q18: =I18*7.48 -> 59.84 | R18: =J18*6 -> 48 | S18: =K18*8.5 -> 68 | T18: =SUM(N18:S18) -> 270.2 | U18: =T18*0.8 -> 216.16
A19: =YEAR(D19) -> 2022 | C19: =VLOOKUP(WEEKDAY(D19),$AE$2:$AF$9,2,0) -> QUARTA | D19: 44867 | E19: =IF(WEEKDAY($D19)<2,0,IF(WEEKDAY($D19)>6,0,7)) -> 7 | F19: =IF(WEEKDAY($D19)<2,0,IF(WEEKDAY($D19)>7,0,7)) -> 7 | H19: =SUM(E19:G19) -> 14 | I19: =IF(WEEKDAY($D19)<2,0,IF(WEEKDAY($D19)>6,0,8)) -> 8 | J19: =IF(WEEKDAY($D19)<2,0,IF(WEEKDAY($D19)>7,0,8)) -> 8 | K19: =IF(WEEKDAY($D19)<2,0,IF(WEEKDAY($D19)>6,0,8)) -> 8 | L19: =SUM(I19:K19) -> 24 | N19: =E19*7.48 -> 52.36 | O19: =F19*6 -> 42 | P19: =G19*8.5 -> 0 | Q19: =I19*7.48 -> 59.84 | R19: =J19*6 -> 48 | S19: =K19*8.5 -> 68 | T19: =SUM(N19:S19) -> 270.2 | U19: =T19*0.8 -> 216.16
A20: =YEAR(D20) -> 2022 | C20: =VLOOKUP(WEEKDAY(D20),$AE$2:$AF$9,2,0) -> QUINTA | D20: 44868 | E20: =IF(WEEKDAY($D20)<2,0,IF(WEEKDAY($D20)>6,0,7)) -> 7 | F20: =IF(WEEKDAY($D20)<2,0,IF(WEEKDAY($D20)>7,0,7)) -> 7 | H20: =SUM(E20:G20) -> 14 | I20: =IF(WEEKDAY($D20)<2,0,IF(WEEKDAY($D20)>6,0,8)) -> 8 | J20: =IF(WEEKDAY($D20)<2,0,IF(WEEKDAY($D20)>7,0,8)) -> 8 | K20: =IF(WEEKDAY($D20)<2,0,IF(WEEKDAY($D20)>6,0,8)) -> 8 | L20: =SUM(I20:K20) -> 24 | N20: =E20*7.48 -> 52.36 | O20: =F20*6 -> 42 | P20: =G20*8.5 -> 0 | Q20: =I20*7.48 -> 59.84 | R20: =J20*6 -> 48 | S20: =K20*8.5 -> 68 | T20: =SUM(N20:S20) -> 270.2 | U20: =T20*0.8 -> 216.16
A21: =YEAR(D21) -> 2022 | C21: =VLOOKUP(WEEKDAY(D21),$AE$2:$AF$9,2,0) -> SEXTA | D21: 44869 | E21: =IF(WEEKDAY($D21)<2,0,IF(WEEKDAY($D21)>6,0,7)) -> 7 | F21: =IF(WEEKDAY($D21)<2,0,IF(WEEKDAY($D21)>7,0,7)) -> 7 | H21: =SUM(E21:G21) -> 14 | I21: =IF(WEEKDAY($D21)<2,0,IF(WEEKDAY($D21)>6,0,8)) -> 8 | J21: =IF(WEEKDAY($D21)<2,0,IF(WEEKDAY($D21)>7,0,8)) -> 8 | K21: =IF(WEEKDAY($D21)<2,0,IF(WEEKDAY($D21)>6,0,8)) -> 8 | L21: =SUM(I21:K21) -> 24 | N21: =E21*7.48 -> 52.36 | O21: =F21*6 -> 42 | P21: =G21*8.5 -> 0 | Q21: =I21*7.48 -> 59.84 | R21: =J21*6 -> 48 | S21: =K21*8.5 -> 68 | T21: =SUM(N21:S21) -> 270.2 | U21: =T21*0.8 -> 216.16
A22: =YEAR(D22) -> 2022 | C22: =VLOOKUP(WEEKDAY(D22),$AE$2:$AF$9,2,0) -> SÁBADO | D22: 44870 | E22: =IF(WEEKDAY($D22)<2,0,IF(WEEKDAY($D22)>6,0,7)) -> 0 | F22: =IF(WEEKDAY($D22)<2,0,IF(WEEKDAY($D22)>7,0,7)) -> 7 | H22: =SUM(E22:G22) -> 7 | I22: =IF(WEEKDAY($D22)<2,0,IF(WEEKDAY($D22)>6,0,8)) -> 0 | J22: =IF(WEEKDAY($D22)<2,0,IF(WEEKDAY($D22)>7,0,8)) -> 8 | K22: =IF(WEEKDAY($D22)<2,0,IF(WEEKDAY($D22)>6,0,8)) -> 0 | L22: =SUM(I22:K22) -> 8 | N22: =E22*7.48 -> 0 | O22: =F22*6 -> 42 | P22: =G22*8.5 -> 0 | Q22: =I22*7.48 -> 0 | R22: =J22*6 -> 48 | S22: =K22*8.5 -> 0 | T22: =SUM(N22:S22) -> 90 | U22: =T22*0.8 -> 72
A23: =YEAR(D23) -> 2022 | C23: =VLOOKUP(WEEKDAY(D23),$AE$2:$AF$9,2,0) -> DOMINGO | D23: 44871 | E23: =IF(WEEKDAY($D23)<2,0,IF(WEEKDAY($D23)>6,0,7)) -> 0 | F23: =IF(WEEKDAY($D23)<2,0,IF(WEEKDAY($D23)>7,0,7)) -> 0 | H23: =SUM(E23:G23) -> 0 | I23: =IF(WEEKDAY($D23)<2,0,IF(WEEKDAY($D23)>6,0,8)) -> 0 | J23: =IF(WEEKDAY($D23)<2,0,IF(WEEKDAY($D23)>7,0,8)) -> 0 | K23: =IF(WEEKDAY($D23)<2,0,IF(WEEKDAY($D23)>6,0,8)) -> 0 | L23: =SUM(I23:K23) -> 0 | N23: =E23*7.48 -> 0 | O23: =F23*6 -> 0 | P23: =G23*8.5 -> 0 | Q23: =I23*7.48 -> 0 | R23: =J23*6 -> 0 | S23: =K23*8.5 -> 0 | T23: =SUM(N23:S23) -> 0 | U23: =T23*0.8 -> 0
A24: =YEAR(D24) -> 2022 | C24: =VLOOKUP(WEEKDAY(D24),$AE$2:$AF$9,2,0) -> SEGUNDA | D24: 44872 | E24: =IF(WEEKDAY($D24)<2,0,IF(WEEKDAY($D24)>6,0,7)) -> 7 | F24: =IF(WEEKDAY($D24)<2,0,IF(WEEKDAY($D24)>7,0,7)) -> 7 | H24: =SUM(E24:G24) -> 14 | I24: =IF(WEEKDAY($D24)<2,0,IF(WEEKDAY($D24)>6,0,8)) -> 8 | J24: =IF(WEEKDAY($D24)<2,0,IF(WEEKDAY($D24)>7,0,8)) -> 8 | K24: =IF(WEEKDAY($D24)<2,0,IF(WEEKDAY($D24)>6,0,8)) -> 8 | L24: =SUM(I24:K24) -> 24 | N24: =E24*7.48 -> 52.36 | O24: =F24*6 -> 42 | P24: =G24*8.5 -> 0 | Q24: =I24*7.48 -> 59.84 | R24: =J24*6 -> 48 | S24: =K24*8.5 -> 68 | T24: =SUM(N24:S24) -> 270.2 | U24: =T24*0.8 -> 216.16
A25: =YEAR(D25) -> 2022 | C25: =VLOOKUP(WEEKDAY(D25),$AE$2:$AF$9,2,0) -> TERÇA | D25: 44873 | E25: =IF(WEEKDAY($D25)<2,0,IF(WEEKDAY($D25)>6,0,7)) -> 7 | F25: =IF(WEEKDAY($D25)<2,0,IF(WEEKDAY($D25)>7,0,7)) -> 7 | H25: =SUM(E25:G25) -> 14 | I25: =IF(WEEKDAY($D25)<2,0,IF(WEEKDAY($D25)>6,0,8)) -> 8 | J25: =IF(WEEKDAY($D25)<2,0,IF(WEEKDAY($D25)>7,0,8)) -> 8 | K25: =IF(WEEKDAY($D25)<2,0,IF(WEEKDAY($D25)>6,0,8)) -> 8 | L25: =SUM(I25:K25) -> 24 | N25: =E25*7.48 -> 52.36 | O25: =F25*6 -> 42 | P25: =G25*8.5 -> 0 | Q25: =I25*7.48 -> 59.84 | R25: =J25*6 -> 48 | S25: =K25*8.5 -> 68 | T25: =SUM(N25:S25) -> 270.2 | U25: =T25*0.8 -> 216.16
A26: =YEAR(D26) -> 2022 | C26: =VLOOKUP(WEEKDAY(D26),$AE$2:$AF$9,2,0) -> QUARTA | D26: 44874 | E26: =IF(WEEKDAY($D26)<2,0,IF(WEEKDAY($D26)>6,0,7)) -> 7 | F26: =IF(WEEKDAY($D26)<2,0,IF(WEEKDAY($D26)>7,0,7)) -> 7 | H26: =SUM(E26:G26) -> 14 | I26: =IF(WEEKDAY($D26)<2,0,IF(WEEKDAY($D26)>6,0,8)) -> 8 | J26: =IF(WEEKDAY($D26)<2,0,IF(WEEKDAY($D26)>7,0,8)) -> 8 | K26: =IF(WEEKDAY($D26)<2,0,IF(WEEKDAY($D26)>6,0,8)) -> 8 | L26: =SUM(I26:K26) -> 24 | N26: =E26*7.48 -> 52.36 | O26: =F26*6 -> 42 | P26: =G26*8.5 -> 0 | Q26: =I26*7.48 -> 59.84 | R26: =J26*6 -> 48 | S26: =K26*8.5 -> 68 | T26: =SUM(N26:S26) -> 270.2 | U26: =T26*0.8 -> 216.16
... A126: =YEAR(D126) -> 2023 | C126: =VLOOKUP(WEEKDAY(D126),$AE$2:$AF$9,2,0) -> SEXTA | D126: 44974 | E126: =IF(WEEKDAY($D126)<2,0,IF(WEEKDAY($D126)>6,0,7)) -> 7 | F126: =IF(WEEKDAY($D126)<2,0,IF(WEEKDAY($D126)>7,0,7)) -> 7 | H126: =SUM(E126:G126) -> 14 | I126: =IF(WEEKDAY($D126)<2,0,IF(WEEKDAY($D126)>6,0,8)) -> 8 | J126: =IF(WEEKDAY($D126)<2,0,IF(WEEKDAY($D126)>7,0,8)) -> 8 | K126: =IF(WEEKDAY($D126)<2,0,IF(WEEKDAY($D126)>6,0,8)) -> 8 | L126: =SUM(I126:K126) -> 24 | N126: =E126*7.48 -> 52.36 | O126: =F126*6 -> 42 | P126: =G126*8.5 -> 0 | Q126: =I126*7.48 -> 59.84 | R126: =J126*6 -> 48 | S126: =K126*8.5 -> 68 | T126: =SUM(N126:S126) -> 270.2 | U126: =T126*0.8 -> 216.16
A127: =YEAR(D127) -> 2023 | B127: =VLOOKUP(MONTH(D127),$AG$2:$AH$14,2,0) -> FEVEREIRO | C127: =VLOOKUP(WEEKDAY(D127),$AE$2:$AF$9,2,0) -> SÁBADO | D127: 44975 | E127: =IF(WEEKDAY($D127)<2,0,IF(WEEKDAY($D127)>6,0,7)) -> 0 | F127: =IF(WEEKDAY($D127)<2,0,IF(WEEKDAY($D127)>7,0,7)) -> 7 | H127: =SUM(E127:G127) -> 7 | I127: =IF(WEEKDAY($D127)<2,0,IF(WEEKDAY($D127)>6,0,8)) -> 0 | J127: =IF(WEEKDAY($D127)<2,0,IF(WEEKDAY($D127)>7,0,8)) -> 8 | K127: =IF(WEEKDAY($D127)<2,0,IF(WEEKDAY($D127)>6,0,8)) -> 0 | L127: =SUM(I127:K127) -> 8 | N127: =E127*7.48 -> 0 | O127: =F127*6 -> 42 | P127: =G127*8.5 -> 0 | Q127: =I127*7.48 -> 0 | R127: =J127*6 -> 48 | S127: =K127*8.5 -> 0 | T127: =SUM(N127:S127) -> 90 | U127: =T127*0.8 -> 72
A128: =YEAR(D128) -> 2023 | B128: =VLOOKUP(MONTH(D128),$AG$2:$AH$14,2,0) -> FEVEREIRO | C128: =VLOOKUP(WEEKDAY(D128),$AE$2:$AF$9,2,0) -> DOMINGO | D128: 44976 | E128: =IF(WEEKDAY($D128)<2,0,IF(WEEKDAY($D128)>6,0,7)) -> 0 | F128: =IF(WEEKDAY($D128)<2,0,IF(WEEKDAY($D128)>7,0,7)) -> 0 | H128: =SUM(E128:G128) -> 0 | I128: =IF(WEEKDAY($D128)<2,0,IF(WEEKDAY($D128)>6,0,8)) -> 0 | J128: =IF(WEEKDAY($D128)<2,0,IF(WEEKDAY($D128)>7,0,8)) -> 0 | K128: =IF(WEEKDAY($D128)<2,0,IF(WEEKDAY($D128)>6,0,8)) -> 0 | L128: =SUM(I128:K128) -> 0 | N128: =E128*7.48 -> 0 | O128: =F128*6 -> 0 | P128: =G128*8.5 -> 0 | Q128: =I128*7.48 -> 0 | R128: =J128*6 -> 0 | S128: =K128*8.5 -> 0 | T128: =SUM(N128:S128) -> 0 | U128: =T128*0.8 -> 0
A129: =YEAR(D129) -> 2023 | B129: =VLOOKUP(MONTH(D129),$AG$2:$AH$14,2,0) -> FEVEREIRO | C129: =VLOOKUP(WEEKDAY(D129),$AE$2:$AF$9,2,0) -> SEGUNDA | D129: 44977 | E129: =IF(WEEKDAY($D129)<2,0,IF(WEEKDAY($D129)>6,0,7)) -> 7 | F129: =IF(WEEKDAY($D129)<2,0,IF(WEEKDAY($D129)>7,0,7)) -> 7 | H129: =SUM(E129:G129) -> 14 | I129: =IF(WEEKDAY($D129)<2,0,IF(WEEKDAY($D129)>6,0,8)) -> 8 | J129: =IF(WEEKDAY($D129)<2,0,IF(WEEKDAY($D129)>7,0,8)) -> 8 | K129: =IF(WEEKDAY($D129)<2,0,IF(WEEKDAY($D129)>6,0,8)) -> 8 | L129: =SUM(I129:K129) -> 24 | N129: =E129*7.48 -> 52.36 | O129: =F129*6 -> 42 | P129: =G129*8.5 -> 0 | Q129: =I129*7.48 -> 59.84 | R129: =J129*6 -> 48 | S129: =K129*8.5 -> 68 | T129: =SUM(N129:S129) -> 270.2 | U129: =T129*0.8 -> 216.16
A130: =YEAR(D130) -> 2023 | B130: =VLOOKUP(MONTH(D130),$AG$2:$AH$14,2,0) -> FEVEREIRO | C130: =VLOOKUP(WEEKDAY(D130),$AE$2:$AF$9,2,0) -> TERÇA | D130: 44978 | E130: =IF(WEEKDAY($D130)<2,0,IF(WEEKDAY($D130)>6,0,7)) -> 7 | F130: =IF(WEEKDAY($D130)<2,0,IF(WEEKDAY($D130)>7,0,7)) -> 7 | H130: =SUM(E130:G130) -> 14 | I130: =IF(WEEKDAY($D130)<2,0,IF(WEEKDAY($D130)>6,0,8)) -> 8 | J130: =IF(WEEKDAY($D130)<2,0,IF(WEEKDAY($D130)>7,0,8)) -> 8 | K130: =IF(WEEKDAY($D130)<2,0,IF(WEEKDAY($D130)>6,0,8)) -> 8 | L130: =SUM(I130:K130) -> 24 | N130: =E130*7.48 -> 52.36 | O130: =F130*6 -> 42 | P130: =G130*8.5 -> 0 | Q130: =I130*7.48 -> 59.84 | R130: =J130*6 -> 48 | S130: =K130*8.5 -> 68 | T130: =SUM(N130:S130) -> 270.2 | U130: =T130*0.8 -> 216.16
A131: =YEAR(D131) -> 2023 | B131: =VLOOKUP(MONTH(D131),$AG$2:$AH$14,2,0) -> FEVEREIRO | C131: =VLOOKUP(WEEKDAY(D131),$AE$2:$AF$9,2,0) -> QUARTA | D131: 44979 | E131: =IF(WEEKDAY($D131)<2,0,IF(WEEKDAY($D131)>6,0,7)) -> 7 | F131: =IF(WEEKDAY($D131)<2,0,IF(WEEKDAY($D131)>7,0,7)) -> 7 | H131: =SUM(E131:G131) -> 14 | I131: =IF(WEEKDAY($D131)<2,0,IF(WEEKDAY($D131)>6,0,8)) -> 8 | J131: =IF(WEEKDAY($D131)<2,0,IF(WEEKDAY($D131)>7,0,8)) -> 8 | K131: =IF(WEEKDAY($D131)<2,0,IF(WEEKDAY($D131)>6,0,8)) -> 8 | L131: =SUM(I131:K131) -> 24 | N131: =E131*7.48 -> 52.36 | O131: =F131*6 -> 42 | P131: =G131*8.5 -> 0 | Q131: =I131*7.48 -> 59.84 | R131: =J131*6 -> 48 | S131: =K131*8.5 -> 68 | T131: =SUM(N131:S131) -> 270.2 | U131: =T131*0.8 -> 216.16
A132: =YEAR(D132) -> 2023 | B132: =VLOOKUP(MONTH(D132),$AG$2:$AH$14,2,0) -> FEVEREIRO | C132: =VLOOKUP(WEEKDAY(D132),$AE$2:$AF$9,2,0) -> QUINTA | D132: 44980 | E132: =IF(WEEKDAY($D132)<2,0,IF(WEEKDAY($D132)>6,0,7)) -> 7 | F132: =IF(WEEKDAY($D132)<2,0,IF(WEEKDAY($D132)>7,0,7)) -> 7 | H132: =SUM(E132:G132) -> 14 | I132: =IF(WEEKDAY($D132)<2,0,IF(WEEKDAY($D132)>6,0,8)) -> 8 | J132: =IF(WEEKDAY($D132)<2,0,IF(WEEKDAY($D132)>7,0,8)) -> 8 | K132: =IF(WEEKDAY($D132)<2,0,IF(WEEKDAY($D132)>6,0,8)) -> 8 | L132: =SUM(I132:K132) -> 24 | N132: =E132*7.48 -> 52.36 | O132: =F132*6 -> 42 | P132: =G132*8.5 -> 0 | Q132: =I132*7.48 -> 59.84 | R132: =J132*6 -> 48 | S132: =K132*8.5 -> 68 | T132: =SUM(N132:S132) -> 270.2 | U132: =T132*0.8 -> 216.16
A133: =YEAR(D133) -> 2023 | B133: =VLOOKUP(MONTH(D133),$AG$2:$AH$14,2,0) -> FEVEREIRO | C133: =VLOOKUP(WEEKDAY(D133),$AE$2:$AF$9,2,0) -> SEXTA | D133: 44981 | E133: =IF(WEEKDAY($D133)<2,0,IF(WEEKDAY($D133)>6,0,7)) -> 7 | F133: =IF(WEEKDAY($D133)<2,0,IF(WEEKDAY($D133)>7,0,7)) -> 7 | H133: =SUM(E133:G133) -> 14 | I133: =IF(WEEKDAY($D133)<2,0,IF(WEEKDAY($D133)>6,0,8)) -> 8 | J133: =IF(WEEKDAY($D133)<2,0,IF(WEEKDAY($D133)>7,0,8)) -> 8 | K133: =IF(WEEKDAY($D133)<2,0,IF(WEEKDAY($D133)>6,0,8)) -> 8 | L133: =SUM(I133:K133) -> 24 | N133: =E133*7.48 -> 52.36 | O133: =F133*6 -> 42 | P133: =G133*8.5 -> 0 | Q133: =I133*7.48 -> 59.84 | R133: =J133*6 -> 48 | S133: =K133*8.5 -> 68 | T133: =SUM(N133:S133) -> 270.2 | U133: =T133*0.8 -> 216.16
A134: =YEAR(D134) -> 2023 | B134: =VLOOKUP(MONTH(D134),$AG$2:$AH$14,2,0) -> FEVEREIRO | C134: =VLOOKUP(WEEKDAY(D134),$AE$2:$AF$9,2,0) -> SÁBADO | D134: 44982 | E134: =IF(WEEKDAY($D134)<2,0,IF(WEEKDAY($D134)>6,0,7)) -> 0 | F134: =IF(WEEKDAY($D134)<2,0,IF(WEEKDAY($D134)>7,0,7)) -> 7 | H134: =SUM(E134:G134) -> 7 | I134: =IF(WEEKDAY($D134)<2,0,IF(WEEKDAY($D134)>6,0,8)) -> 0 | J134: =IF(WEEKDAY($D134)<2,0,IF(WEEKDAY($D134)>7,0,8)) -> 8 | K134: =IF(WEEKDAY($D134)<2,0,IF(WEEKDAY($D134)>6,0,8)) -> 0 | L134: =SUM(I134:K134) -> 8 | N134: =E134*7.48 -> 0 | O134: =F134*6 -> 42 | P134: =G134*8.5 -> 0 | Q134: =I134*7.48 -> 0 | R134: =J134*6 -> 48 | S134: =K134*8.5 -> 0 | T134: =SUM(N134:S134) -> 90 | U134: =T134*0.8 -> 72
A135: =YEAR(D135) -> 2023 | B135: =VLOOKUP(MONTH(D135),$AG$2:$AH$14,2,0) -> FEVEREIRO | C135: =VLOOKUP(WEEKDAY(D135),$AE$2:$AF$9,2,0) -> DOMINGO | D135: 44983 | E135: =IF(WEEKDAY($D135)<2,0,IF(WEEKDAY($D135)>6,0,7)) -> 0 | F135: =IF(WEEKDAY($D135)<2,0,IF(WEEKDAY($D135)>7,0,7)) -> 0 | H135: =SUM(E135:G135) -> 0 | I135: =IF(WEEKDAY($D135)<2,0,IF(WEEKDAY($D135)>6,0,8)) -> 0 | J135: =IF(WEEKDAY($D135)<2,0,IF(WEEKDAY($D135)>7,0,8)) -> 0 | K135: =IF(WEEKDAY($D135)<2,0,IF(WEEKDAY($D135)>6,0,8)) -> 0 | L135: =SUM(I135:K135) -> 0 | N135: =E135*7.48 -> 0 | O135: =F135*6 -> 0 | P135: =G135*8.5 -> 0 | Q135: =I135*7.48 -> 0 | R135: =J135*6 -> 0 | S135: =K135*8.5 -> 0 | T135: =SUM(N135:S135) -> 0 | U135: =T135*0.8 -> 0
A136: =YEAR(D136) -> 2023 | B136: =VLOOKUP(MONTH(D136),$AG$2:$AH$14,2,0) -> FEVEREIRO | C136: =VLOOKUP(WEEKDAY(D136),$AE$2:$AF$9,2,0) -> SEGUNDA | D136: 44984 | E136: =IF(WEEKDAY($D136)<2,0,IF(WEEKDAY($D136)>6,0,7)) -> 7 | F136: =IF(WEEKDAY($D136)<2,0,IF(WEEKDAY($D136)>7,0,7)) -> 7 | H136: =SUM(E136:G136) -> 14 | I136: =IF(WEEKDAY($D136)<2,0,IF(WEEKDAY($D136)>6,0,8)) -> 8 | J136: =IF(WEEKDAY($D136)<2,0,IF(WEEKDAY($D136)>7,0,8)) -> 8 | K136: =IF(WEEKDAY($D136)<2,0,IF(WEEKDAY($D136)>6,0,8)) -> 8 | L136: =SUM(I136:K136) -> 24 | N136: =E136*7.48 -> 52.36 | O136: =F136*6 -> 42 | P136: =G136*8.5 -> 0 | Q136: =I136*7.48 -> 59.84 | R136: =J136*6 -> 48 | S136: =K136*8.5 -> 68 | T136: =SUM(N136:S136) -> 270.2 | U136: =T136*0.8 -> 216.16
A137: =YEAR(D137) -> 2023 | B137: =VLOOKUP(MONTH(D137),$AG$2:$AH$14,2,0) -> FEVEREIRO | C137: =VLOOKUP(WEEKDAY(D137),$AE$2:$AF$9,2,0) -> TERÇA | D137: 44985 | E137: =IF(WEEKDAY($D137)<2,0,IF(WEEKDAY($D137)>6,0,7)) -> 7 | F137: =IF(WEEKDAY($D137)<2,0,IF(WEEKDAY($D137)>7,0,7)) -> 7 | H137: =SUM(E137:G137) -> 14 | I137: =IF(WEEKDAY($D137)<2,0,IF(WEEKDAY($D137)>6,0,8)) -> 8 | J137: =IF(WEEKDAY($D137)<2,0,IF(WEEKDAY($D137)>7,0,8)) -> 8 | K137: =IF(WEEKDAY($D137)<2,0,IF(WEEKDAY($D137)>6,0,8)) -> 8 | L137: =SUM(I137:K137) -> 24 | N137: =E137*7.48 -> 52.36 | O137: =F137*6 -> 42 | P137: =G137*8.5 -> 0 | Q137: =I137*7.48 -> 59.84 | R137: =J137*6 -> 48 | S137: =K137*8.5 -> 68 | T137: =SUM(N137:S137) -> 270.2 | U137: =T137*0.8 -> 216.16
A138: =YEAR(D138) -> 2023 | B138: =VLOOKUP(MONTH(D138),$AG$2:$AH$14,2,0) -> MARÇO | C138: =VLOOKUP(WEEKDAY(D138),$AE$2:$AF$9,2,0) -> QUARTA | D138: 44986 | E138: =IF(WEEKDAY($D138)<2,0,IF(WEEKDAY($D138)>6,0,7)) -> 7 | F138: =IF(WEEKDAY($D138)<2,0,IF(WEEKDAY($D138)>7,0,7)) -> 7 | H138: =SUM(E138:G138) -> 14 | I138: =IF(WEEKDAY($D138)<2,0,IF(WEEKDAY($D138)>6,0,8)) -> 8 | J138: =IF(WEEKDAY($D138)<2,0,IF(WEEKDAY($D138)>7,0,8)) -> 8 | K138: =IF(WEEKDAY($D138)<2,0,IF(WEEKDAY($D138)>6,0,8)) -> 8 | L138: =SUM(I138:K138) -> 24 | N138: =E138*7.48 -> 52.36 | O138: =F138*6 -> 42 | P138: =G138*8.5 -> 0 | Q138: =I138*7.48 -> 59.84 | R138: =J138*6 -> 48 | S138: =K138*8.5 -> 68 | T138: =SUM(N138:S138) -> 270.2 | U138: =T138*0.8 -> 216.16
... A523: =YEAR(D523) -> 2024 | B523: =VLOOKUP(MONTH(D523),$AG$2:$AH$14,2,0) -> MARÇO | C523: =VLOOKUP(WEEKDAY(D523),$AE$2:$AF$9,2,0) -> QUARTA | D523: 45371 | E523: =IF(WEEKDAY($D523)<2,0,IF(WEEKDAY($D523)>6,0,7)) -> 7 | F523: =IF(WEEKDAY($D523)<2,0,IF(WEEKDAY($D523)>7,0,7)) -> 7 | H523: =SUM(E523:G523) -> 14 | I523: =IF(WEEKDAY($D523)<2,0,IF(WEEKDAY($D523)>6,0,8)) -> 8 | J523: =IF(WEEKDAY($D523)<2,0,IF(WEEKDAY($D523)>7,0,8)) -> 8 | K523: =IF(WEEKDAY($D523)<2,0,IF(WEEKDAY($D523)>6,0,8)) -> 8 | L523: =SUM(I523:K523) -> 24 | N523: =E523*7.48 -> 52.36 | O523: =F523*6 -> 42 | P523: =G523*8.5 -> 0 | Q523: =I523*7.48 -> 59.84 | R523: =J523*6 -> 48 | S523: =K523*8.5 -> 68 | T523: =SUM(N523:S523) -> 270.2 | U523: =T523*0.8 -> 216.16
A524: =YEAR(D524) -> 2024 | B524: =VLOOKUP(MONTH(D524),$AG$2:$AH$14,2,0) -> MARÇO | C524: =VLOOKUP(WEEKDAY(D524),$AE$2:$AF$9,2,0) -> QUINTA | D524: 45372 | E524: =IF(WEEKDAY($D524)<2,0,IF(WEEKDAY($D524)>6,0,7)) -> 7 | F524: =IF(WEEKDAY($D524)<2,0,IF(WEEKDAY($D524)>7,0,7)) -> 7 | I524: =IF(WEEKDAY($D524)<2,0,IF(WEEKDAY($D524)>6,0,8)) -> 8 | J524: =IF(WEEKDAY($D524)<2,0,IF(WEEKDAY($D524)>7,0,8)) -> 8 | K524: =IF(WEEKDAY($D524)<2,0,IF(WEEKDAY($D524)>6,0,8)) -> 8 | N524: =E524*7.48 -> 52.36 | O524: =F524*6 -> 42 | P524: =G524*8.5 -> 0 | Q524: =I524*7.48 -> 59.84 | R524: =J524*6 -> 48 | S524: =K524*8.5 -> 68 | T524: =SUM(N524:S524) -> 270.2 | U524: =T524*0.8 -> 216.16
...

Sheet EFICIÊNIA DA PRODUÇÃO
A3: Ano | B3: Mês | C3: Data | D3: LINHA 1 | I3: LINHA 2
D4: NOITE | E4: DIA | F4: TARDE | G4: TOTAL | I4: NOITE | J4: DIA | K4: TARDE | L4: TOTAL
A6: =IF(C6>0,YEAR(C6),0) -> 2022 | B6: =IF(C6>0,MONTH(C6),0) -> 10 | C6: 44853 | D6: =SUMIFS('PRODUÇÃO LINHA 1'!$J:$J,'PRODUÇÃO LINHA 1'!$D:$D,'EFICIÊNIA DA PRODUÇÃO'!$C6,'PRODUÇÃO LINHA 1'!$G:$G,'EFICIÊNIA DA PRODUÇÃO'!D$4)/SUMIFS('HOMEM X HORA'!N:N,'HOMEM X HORA'!$D:$D,'EFICIÊNIA DA PRODUÇÃO'!$C6) -> 0 | E6: =SUMIFS('HOMEM X HORA'!O:O,'HOMEM X HORA'!$D:$D,'EFICIÊNIA DA PRODUÇÃO'!$C6) -> 42 | F6: =SUMIFS('HOMEM X HORA'!P:P,'HOMEM X HORA'!$D:$D,'EFICIÊNIA DA PRODUÇÃO'!$C6) -> 0
A7: =IF(C7>0,YEAR(C7),0) -> 2022 | B7: =IF(C7>0,MONTH(C7),0) -> 9 | C7: 44824 | D7: =SUMIFS('HOMEM X HORA'!N:N,'HOMEM X HORA'!D:D,'EFICIÊNIA DA PRODUÇÃO'!C7)*3600000 -> 0
A8: =IF(C8>0,YEAR(C8),0) -> 2022 | B8: =IF(C8>0,MONTH(C8),0) -> 9 | C8: 44825 | D8: =SUMIFS('HOMEM X HORA'!N:N,'HOMEM X HORA'!D:D,'EFICIÊNIA DA PRODUÇÃO'!C8)*3600000 -> 0
A9: =IF(C9>0,YEAR(C9),0) -> 2022 | B9: =IF(C9>0,MONTH(C9),0) -> 9 | C9: 44826 | D9: =SUMIFS('HOMEM X HORA'!N:N,'HOMEM X HORA'!D:D,'EFICIÊNIA DA PRODUÇÃO'!C9)*3600000 -> 0
